Workbook
Name Apr: 横カレンダー!DaysAndWeeks+DATE(CalendarYear,4,1)-WEEKDAY(DATE(CalendarYear,4,1),横カレンダー!WeekdayOption)+1
Name Apr: 予算!DaysAndWeeks+DATE(CalendarYear,4,1)-WEEKDAY(DATE(CalendarYear,4,1),予算!WeekdayOption)+1
Name Apr: DaysAndWeeks+DATE(CalendarYear,4,1)-WEEKDAY(DATE(CalendarYear,4,1),WeekdayOption)+1
Name Aug: 横カレンダー!DaysAndWeeks+DATE(CalendarYear,8,1)-WEEKDAY(DATE(CalendarYear,8,1),横カレンダー!WeekdayOption)+1
Name Aug: 予算!DaysAndWeeks+DATE(CalendarYear,8,1)-WEEKDAY(DATE(CalendarYear,8,1),予算!WeekdayOption)+1
Name Aug: DaysAndWeeks+DATE(CalendarYear,8,1)-WEEKDAY(DATE(CalendarYear,8,1),WeekdayOption)+1
Name CalendarYear: #REF!
Name DayHeaders: LEFT(TEXT(#REF!,"aaa"),2)
Name DaysAndWeeks: {0,1,2,3,4,5,6} + {0;1;2;3;4;5}*7
Name DaysAndWeeks: {0,1,2,3,4,5,6} + {0;1;2;3;4;5}*7
Name DaysAndWeeks: {0,1,2,3,4,5,6} + {0;1;2;3;4;5}*7
Name Dec: 横カレンダー!DaysAndWeeks+DATE(CalendarYear,12,1)-WEEKDAY(DATE(CalendarYear,12,1),横カレンダー!WeekdayOption)+1
Name Dec: 予算!DaysAndWeeks+DATE(CalendarYear,12,1)-WEEKDAY(DATE(CalendarYear,12,1),予算!WeekdayOption)+1
Name Dec: DaysAndWeeks+DATE(CalendarYear,12,1)-WEEKDAY(DATE(CalendarYear,12,1),WeekdayOption)+1
Name Feb: 横カレンダー!DaysAndWeeks+DATE(CalendarYear,2,1)-WEEKDAY(DATE(CalendarYear,2,1),横カレンダー!WeekdayOption)+1
Name Feb: 予算!DaysAndWeeks+DATE(CalendarYear,2,1)-WEEKDAY(DATE(CalendarYear,2,1),予算!WeekdayOption)+1
Name Feb: DaysAndWeeks+DATE(CalendarYear,2,1)-WEEKDAY(DATE(CalendarYear,2,1),WeekdayOption)+1
Name Jan: 横カレンダー!DaysAndWeeks+DATE(CalendarYear,1,1)-WEEKDAY(DATE(CalendarYear,1,1),横カレンダー!WeekdayOption)+1
Name Jan: 予算!DaysAndWeeks+DATE(CalendarYear,1,1)-WEEKDAY(DATE(CalendarYear,1,1),予算!WeekdayOption)+1
Name Jan: DaysAndWeeks+DATE(CalendarYear,1,1)-WEEKDAY(DATE(CalendarYear,1,1),WeekdayOption)+1
Name Jul: 横カレンダー!DaysAndWeeks+DATE(CalendarYear,7,1)-WEEKDAY(DATE(CalendarYear,7,1),横カレンダー!WeekdayOption)+1
Name Jul: 予算!DaysAndWeeks+DATE(CalendarYear,7,1)-WEEKDAY(DATE(CalendarYear,7,1),予算!WeekdayOption)+1
Name Jul: DaysAndWeeks+DATE(CalendarYear,7,1)-WEEKDAY(DATE(CalendarYear,7,1),WeekdayOption)+1
Name Jun: 横カレンダー!DaysAndWeeks+DATE(CalendarYear,6,1)-WEEKDAY(DATE(CalendarYear,6,1),横カレンダー!WeekdayOption)+1
Name Jun: 予算!DaysAndWeeks+DATE(CalendarYear,6,1)-WEEKDAY(DATE(CalendarYear,6,1),予算!WeekdayOption)+1
Name Jun: DaysAndWeeks+DATE(CalendarYear,6,1)-WEEKDAY(DATE(CalendarYear,6,1),WeekdayOption)+1
Name Mar: 横カレンダー!DaysAndWeeks+DATE(CalendarYear,3,1)-WEEKDAY(DATE(CalendarYear,3,1),横カレンダー!WeekdayOption)+1
Name Mar: 予算!DaysAndWeeks+DATE(CalendarYear,3,1)-WEEKDAY(DATE(CalendarYear,3,1),予算!WeekdayOption)+1
Name Mar: DaysAndWeeks+DATE(CalendarYear,3,1)-WEEKDAY(DATE(CalendarYear,3,1),WeekdayOption)+1
Name May: 横カレンダー!DaysAndWeeks+DATE(CalendarYear,5,1)-WEEKDAY(DATE(CalendarYear,5,1),横カレンダー!WeekdayOption)+1
Name May: 予算!DaysAndWeeks+DATE(CalendarYear,5,1)-WEEKDAY(DATE(CalendarYear,5,1),予算!WeekdayOption)+1
Name May: DaysAndWeeks+DATE(CalendarYear,5,1)-WEEKDAY(DATE(CalendarYear,5,1),WeekdayOption)+1
Name MonthHeaders: UPPER(TEXT(#REF!,"m月"))
Name Nov: 横カレンダー!DaysAndWeeks+DATE(CalendarYear,11,1)-WEEKDAY(DATE(CalendarYear,11,1),横カレンダー!WeekdayOption)+1
Name Nov: 予算!DaysAndWeeks+DATE(CalendarYear,11,1)-WEEKDAY(DATE(CalendarYear,11,1),予算!WeekdayOption)+1
Name Nov: DaysAndWeeks+DATE(CalendarYear,11,1)-WEEKDAY(DATE(CalendarYear,11,1),WeekdayOption)+1
Name Oct: 横カレンダー!DaysAndWeeks+DATE(CalendarYear,10,1)-WEEKDAY(DATE(CalendarYear,10,1),横カレンダー!WeekdayOption)+1
Name Oct: 予算!DaysAndWeeks+DATE(CalendarYear,10,1)-WEEKDAY(DATE(CalendarYear,10,1),予算!WeekdayOption)+1
Name Oct: DaysAndWeeks+DATE(CalendarYear,10,1)-WEEKDAY(DATE(CalendarYear,10,1),WeekdayOption)+1
Name Sep: 横カレンダー!DaysAndWeeks+DATE(CalendarYear,9,1)-WEEKDAY(DATE(CalendarYear,9,1),横カレンダー!WeekdayOption)+1
Name Sep: 予算!DaysAndWeeks+DATE(CalendarYear,9,1)-WEEKDAY(DATE(CalendarYear,9,1),予算!WeekdayOption)+1
Name Sep: DaysAndWeeks+DATE(CalendarYear,9,1)-WEEKDAY(DATE(CalendarYear,9,1),WeekdayOption)+1
Name WeekdayOption: MATCH(WeekStart,横カレンダー!曜日,0)+10
Name WeekdayOption: MATCH(WeekStart,予算!曜日,0)+10
Name WeekdayOption: MATCH(WeekStart,曜日,0)+10
Name WeekStart: #REF!
Name 修正ランク: #REF!,#REF!,#REF!,#REF!,#REF!,#REF!,#REF!,#REF!,#REF!,#REF!,#REF!,#REF!
Name 修正ランク: #REF!,#REF!,#REF!,#REF!,#REF!,#REF!,#REF!,#REF!,#REF!,#REF!,#REF!,#REF!
Name 修正案: #REF!,#REF!,#REF!,#REF!,#REF!,#REF!
Name 曜日: {"月曜日","火曜日","水曜日","木曜日","金曜日","土曜日","日曜日"}
Name 曜日: {"月曜日","火曜日","水曜日","木曜日","金曜日","土曜日","日曜日"}
Name 曜日: {"月曜日","火曜日","水曜日","木曜日","金曜日","土曜日","日曜日"}

Sheet 横カレンダー
C1: =C3-TODAY() -> -17 | D1: =D3-TODAY() -> -16 | E1: =E3-TODAY() -> -15 | F1: =F3-TODAY() -> -14 | G1: =G3-TODAY() -> -13 | H1: =H3-TODAY() -> -12 | I1: =I3-TODAY() -> -11 | J1: =J3-TODAY() -> -10 | ... KT1: =KT3-TODAY() -> 286
C2: =TEXT(C$3,"yyyy年m月") -> 2025年11月 | D2: =TEXT(D$3,"yyyy年m月") -> 2025年11月 | E2: =TEXT(E$3,"yyyy年m月") -> 2025年11月 | F2: =TEXT(F$3,"yyyy年m月") -> 2025年11月 | G2: =TEXT(G$3,"yyyy年m月") -> 2025年11月 | H2: =TEXT(H$3,"yyyy年m月") -> 2025年11月 | I2: =TEXT(I$3,"yyyy年m月") -> 2025年11月 | J2: =TEXT(J$3,"yyyy年m月") -> 2025年11月 | ... KT2: =TEXT(KT$3,"yyyy年m月") -> 2026年8月
B3: 45962 | C3: =B3 -> 45962 | D3: =C3+1 -> 45963 | E3: =D3+1 -> 45964 | F3: =E3+1 -> 45965 | G3: =F3+1 -> 45966 | H3: =G3+1 -> 45967 | I3: =H3+1 -> 45968 | J3: =I3+1 -> 45969 | K3: =J3+1 -> 45970 | ... KT3: =KS3+1 -> 46265
A4: 1 | B4: =カレンダー!B$16 -> ラグジュアリープールヴィラ(単泊) | H4: =IFERROR(IF(AND(H29="",H16=""),"",IF(H29="",H16,H29)),"") -> H | I4: =IFERROR(IF(AND(I29="",I16=""),"",IF(I29="",I16,I29)),"") -> G | J4: =IFERROR(IF(AND(J29="",J16=""),"",IF(J29="",J16,J29)),"") -> P | K4: =IFERROR(IF(AND(K29="",K16=""),"",IF(K29="",K16,K29)),"") -> I | L4: =IFERROR(IF(AND(L29="",L16=""),"",IF(L29="",L16,L29)),"") -> K | M4: =IFERROR(IF(AND(M29="",M16=""),"",IF(M29="",M16,M29)),"") -> H | N4: =IFERROR(IF(AND(N29="",N16=""),"",IF(N29="",N16,N29)),"") -> E | O4: =IFERROR(IF(AND(O29="",O16=""),"",IF(O29="",O16,O29)),"") -> H | ... KT4: =IFERROR(IF(AND(KT29="",KT16=""),"",IF(KT29="",KT16,KT29)),"")
A5: =A4+1 -> 2 | B5: =カレンダー!B$17 -> ラグジュアリープールヴィラ(連泊) | H5: =IFERROR(IF(AND(H30="",H17=""),"",IF(H30="",H17,H30)),"") -> H | I5: =IFERROR(IF(AND(I30="",I17=""),"",IF(I30="",I17,I30)),"") -> G | J5: =IFERROR(IF(AND(J30="",J17=""),"",IF(J30="",J17,J30)),"") -> P | K5: =IFERROR(IF(AND(K30="",K17=""),"",IF(K30="",K17,K30)),"") -> I | L5: =IFERROR(IF(AND(L30="",L17=""),"",IF(L30="",L17,L30)),"") -> K | M5: =IFERROR(IF(AND(M30="",M17=""),"",IF(M30="",M17,M30)),"") -> H | N5: =IFERROR(IF(AND(N30="",N17=""),"",IF(N30="",N17,N30)),"") -> E | O5: =IFERROR(IF(AND(O30="",O17=""),"",IF(O30="",O17,O30)),"") -> H | ... KT5: =IFERROR(IF(AND(KT30="",KT17=""),"",IF(KT30="",KT17,KT30)),"")
A6: =A5+1 -> 3 | B6: =カレンダー!B$18 -> with SAUNA(単泊) | C6: =IFERROR(IF(AND(C31="",C18=""),"",IF(C31="",C18,C31)),"") -> Q | D6: =IFERROR(IF(AND(D31="",D18=""),"",IF(D31="",D18,D31)),"") -> Q | E6: =IFERROR(IF(AND(E31="",E18=""),"",IF(E31="",E18,E31)),"") -> G | F6: =IFERROR(IF(AND(F31="",F18=""),"",IF(F31="",F18,F31)),"") -> G | G6: =IFERROR(IF(AND(G31="",G18=""),"",IF(G31="",G18,G31)),"") -> G | H6: =IFERROR(IF(AND(H31="",H18=""),"",IF(H31="",H18,H31)),"") -> H | I6: =IFERROR(IF(AND(I31="",I18=""),"",IF(I31="",I18,I31)),"") -> G | J6: =IFERROR(IF(AND(J31="",J18=""),"",IF(J31="",J18,J31)),"") -> P | ... KT6: =IFERROR(IF(AND(KT31="",KT18=""),"",IF(KT31="",KT18,KT31)),"")
A7: =A6+1 -> 4 | B7: =カレンダー!B$19 -> with SAUNA(連泊) | C7: =IFERROR(IF(AND(C32="",C19=""),"",IF(C32="",C19,C32)),"") -> Q | D7: =IFERROR(IF(AND(D32="",D19=""),"",IF(D32="",D19,D32)),"") -> Q | E7: =IFERROR(IF(AND(E32="",E19=""),"",IF(E32="",E19,E32)),"") -> G | F7: =IFERROR(IF(AND(F32="",F19=""),"",IF(F32="",F19,F32)),"") -> G | G7: =IFERROR(IF(AND(G32="",G19=""),"",IF(G32="",G19,G32)),"") -> G | H7: =IFERROR(IF(AND(H32="",H19=""),"",IF(H32="",H19,H32)),"") -> H | I7: =IFERROR(IF(AND(I32="",I19=""),"",IF(I32="",I19,I32)),"") -> G | J7: =IFERROR(IF(AND(J32="",J19=""),"",IF(J32="",J19,J32)),"") -> P | ... KT7: =IFERROR(IF(AND(KT32="",KT19=""),"",IF(KT32="",KT19,KT32)),"")
A8: =A7+1 -> 5 | B8: =カレンダー!B$20 -> 0 | C8: =IFERROR(IF(AND(C33="",C20=""),"",IF(C33="",C20,C33)),"") | D8: =IFERROR(IF(AND(D33="",D20=""),"",IF(D33="",D20,D33)),"") | E8: =IFERROR(IF(AND(E33="",E20=""),"",IF(E33="",E20,E33)),"") | F8: =IFERROR(IF(AND(F33="",F20=""),"",IF(F33="",F20,F33)),"") | G8: =IFERROR(IF(AND(G33="",G20=""),"",IF(G33="",G20,G33)),"") | H8: =IFERROR(IF(AND(H33="",H20=""),"",IF(H33="",H20,H33)),"") | I8: =IFERROR(IF(AND(I33="",I20=""),"",IF(I33="",I20,I33)),"") | J8: =IFERROR(IF(AND(J33="",J20=""),"",IF(J33="",J20,J33)),"") | ... KT8: =IFERROR(IF(AND(KT33="",KT20=""),"",IF(KT33="",KT20,KT33)),"")
A9: =A8+1 -> 6 | B9: =カレンダー!B$21 -> 0 | C9: =IFERROR(IF(AND(C34="",C21=""),"",IF(C34="",C21,C34)),"") | D9: =IFERROR(IF(AND(D34="",D21=""),"",IF(D34="",D21,D34)),"") | E9: =IFERROR(IF(AND(E34="",E21=""),"",IF(E34="",E21,E34)),"") | F9: =IFERROR(IF(AND(F34="",F21=""),"",IF(F34="",F21,F34)),"") | G9: =IFERROR(IF(AND(G34="",G21=""),"",IF(G34="",G21,G34)),"") | H9: =IFERROR(IF(AND(H34="",H21=""),"",IF(H34="",H21,H34)),"") | I9: =IFERROR(IF(AND(I34="",I21=""),"",IF(I34="",I21,I34)),"") | J9: =IFERROR(IF(AND(J34="",J21=""),"",IF(J34="",J21,J34)),"") | ... KT9: =IFERROR(IF(AND(KT34="",KT21=""),"",IF(KT34="",KT21,KT34)),"")
A10: =A9+1 -> 7 | B10: =カレンダー!B$22 -> 0 | C10: =IFERROR(IF(AND(C35="",C22=""),"",IF(C35="",C22,C35)),"") | D10: =IFERROR(IF(AND(D35="",D22=""),"",IF(D35="",D22,D35)),"") | E10: =IFERROR(IF(AND(E35="",E22=""),"",IF(E35="",E22,E35)),"") | F10: =IFERROR(IF(AND(F35="",F22=""),"",IF(F35="",F22,F35)),"") | G10: =IFERROR(IF(AND(G35="",G22=""),"",IF(G35="",G22,G35)),"") | H10: =IFERROR(IF(AND(H35="",H22=""),"",IF(H35="",H22,H35)),"") | I10: =IFERROR(IF(AND(I35="",I22=""),"",IF(I35="",I22,I35)),"") | J10: =IFERROR(IF(AND(J35="",J22=""),"",IF(J35="",J22,J35)),"") | ... KT10: =IFERROR(IF(AND(KT35="",KT22=""),"",IF(KT35="",KT22,KT35)),"")
A11: =A10+1 -> 8 | B11: =カレンダー!B$23 -> 0 | C11: =IFERROR(IF(AND(C36="",C23=""),"",IF(C36="",C23,C36)),"") | D11: =IFERROR(IF(AND(D36="",D23=""),"",IF(D36="",D23,D36)),"") | E11: =IFERROR(IF(AND(E36="",E23=""),"",IF(E36="",E23,E36)),"") | F11: =IFERROR(IF(AND(F36="",F23=""),"",IF(F36="",F23,F36)),"") | G11: =IFERROR(IF(AND(G36="",G23=""),"",IF(G36="",G23,G36)),"") | H11: =IFERROR(IF(AND(H36="",H23=""),"",IF(H36="",H23,H36)),"") | I11: =IFERROR(IF(AND(I36="",I23=""),"",IF(I36="",I23,I36)),"") | J11: =IFERROR(IF(AND(J36="",J23=""),"",IF(J36="",J23,J36)),"") | ... KT11: =IFERROR(IF(AND(KT36="",KT23=""),"",IF(KT36="",KT23,KT36)),"")
A12: =A11+1 -> 9 | B12: =カレンダー!B$24 -> 0 | C12: =IFERROR(IF(AND(C37="",C24=""),"",IF(C37="",C24,C37)),"") | D12: =IFERROR(IF(AND(D37="",D24=""),"",IF(D37="",D24,D37)),"") | E12: =IFERROR(IF(AND(E37="",E24=""),"",IF(E37="",E24,E37)),"") | F12: =IFERROR(IF(AND(F37="",F24=""),"",IF(F37="",F24,F37)),"") | G12: =IFERROR(IF(AND(G37="",G24=""),"",IF(G37="",G24,G37)),"") | H12: =IFERROR(IF(AND(H37="",H24=""),"",IF(H37="",H24,H37)),"") | I12: =IFERROR(IF(AND(I37="",I24=""),"",IF(I37="",I24,I37)),"") | J12: =IFERROR(IF(AND(J37="",J24=""),"",IF(J37="",J24,J37)),"") | ... KT12: =IFERROR(IF(AND(KT37="",KT24=""),"",IF(KT37="",KT24,KT37)),"")
A13: =A12+1 -> 10 | B13: =カレンダー!B$25 -> 0 | C13: =IFERROR(IF(AND(C38="",C25=""),"",IF(C38="",C25,C38)),"") | D13: =IFERROR(IF(AND(D38="",D25=""),"",IF(D38="",D25,D38)),"") | E13: =IFERROR(IF(AND(E38="",E25=""),"",IF(E38="",E25,E38)),"") | F13: =IFERROR(IF(AND(F38="",F25=""),"",IF(F38="",F25,F38)),"") | G13: =IFERROR(IF(AND(G38="",G25=""),"",IF(G38="",G25,G38)),"") | H13: =IFERROR(IF(AND(H38="",H25=""),"",IF(H38="",H25,H38)),"") | I13: =IFERROR(IF(AND(I38="",I25=""),"",IF(I38="",I25,I38)),"") | J13: =IFERROR(IF(AND(J38="",J25=""),"",IF(J38="",J25,J38)),"") | ... KT13: =IFERROR(IF(AND(KT38="",KT25=""),"",IF(KT38="",KT25,KT38)),"")
A16: 1 | B16: =カレンダー!B$16 -> ラグジュアリープールヴィラ(単泊) | C16: =IFERROR(VLOOKUP($B16,INDIRECT(C$2&"!$C$39:$AH$63"),DAY(C$3)+1,FALSE),"") -> Q | D16: =IFERROR(VLOOKUP($B16,INDIRECT(D$2&"!$C$39:$AH$63"),DAY(D$3)+1,FALSE),"") -> Q | E16: =IFERROR(VLOOKUP($B16,INDIRECT(E$2&"!$C$39:$AH$63"),DAY(E$3)+1,FALSE),"") -> G | F16: =IFERROR(VLOOKUP($B16,INDIRECT(F$2&"!$C$39:$AH$63"),DAY(F$3)+1,FALSE),"") -> G | G16: =IFERROR(VLOOKUP($B16,INDIRECT(G$2&"!$C$39:$AH$63"),DAY(G$3)+1,FALSE),"") -> G | H16: =IFERROR(VLOOKUP($B16,INDIRECT(H$2&"!$C$39:$AH$63"),DAY(H$3)+1,FALSE),"") -> H | I16: =IFERROR(VLOOKUP($B16,INDIRECT(I$2&"!$C$39:$AH$63"),DAY(I$3)+1,FALSE),"") -> G | J16: =IFERROR(VLOOKUP($B16,INDIRECT(J$2&"!$C$39:$AH$63"),DAY(J$3)+1,FALSE),"") -> P | ... KT16: =IFERROR(VLOOKUP($B16,INDIRECT(KT$2&"!$C$39:$AH$63"),DAY(KT$3)+1,FALSE),"")
A17: =A16+1 -> 2 | B17: =カレンダー!B$17 -> ラグジュアリープールヴィラ(連泊) | C17: =IFERROR(VLOOKUP($B17,INDIRECT(C$2&"!$C$39:$AH$63"),DAY(C$3)+1,FALSE),"") -> Q | D17: =IFERROR(VLOOKUP($B17,INDIRECT(D$2&"!$C$39:$AH$63"),DAY(D$3)+1,FALSE),"") -> Q | E17: =IFERROR(VLOOKUP($B17,INDIRECT(E$2&"!$C$39:$AH$63"),DAY(E$3)+1,FALSE),"") -> G | F17: =IFERROR(VLOOKUP($B17,INDIRECT(F$2&"!$C$39:$AH$63"),DAY(F$3)+1,FALSE),"") -> G | G17: =IFERROR(VLOOKUP($B17,INDIRECT(G$2&"!$C$39:$AH$63"),DAY(G$3)+1,FALSE),"") -> G | H17: =IFERROR(VLOOKUP($B17,INDIRECT(H$2&"!$C$39:$AH$63"),DAY(H$3)+1,FALSE),"") -> H | I17: =IFERROR(VLOOKUP($B17,INDIRECT(I$2&"!$C$39:$AH$63"),DAY(I$3)+1,FALSE),"") -> G | J17: =IFERROR(VLOOKUP($B17,INDIRECT(J$2&"!$C$39:$AH$63"),DAY(J$3)+1,FALSE),"") -> P | ... KT17: =IFERROR(VLOOKUP($B17,INDIRECT(KT$2&"!$C$39:$AH$63"),DAY(KT$3)+1,FALSE),"")
A18: =A17+1 -> 3 | B18: =カレンダー!B$18 -> with SAUNA(単泊) | C18: =IFERROR(VLOOKUP($B18,INDIRECT(C$2&"!$C$39:$AH$63"),DAY(C$3)+1,FALSE),"") -> Q | D18: =IFERROR(VLOOKUP($B18,INDIRECT(D$2&"!$C$39:$AH$63"),DAY(D$3)+1,FALSE),"") -> Q | E18: =IFERROR(VLOOKUP($B18,INDIRECT(E$2&"!$C$39:$AH$63"),DAY(E$3)+1,FALSE),"") -> G | F18: =IFERROR(VLOOKUP($B18,INDIRECT(F$2&"!$C$39:$AH$63"),DAY(F$3)+1,FALSE),"") -> G | G18: =IFERROR(VLOOKUP($B18,INDIRECT(G$2&"!$C$39:$AH$63"),DAY(G$3)+1,FALSE),"") -> G | H18: =IFERROR(VLOOKUP($B18,INDIRECT(H$2&"!$C$39:$AH$63"),DAY(H$3)+1,FALSE),"") -> H | I18: =IFERROR(VLOOKUP($B18,INDIRECT(I$2&"!$C$39:$AH$63"),DAY(I$3)+1,FALSE),"") -> G | J18: =IFERROR(VLOOKUP($B18,INDIRECT(J$2&"!$C$39:$AH$63"),DAY(J$3)+1,FALSE),"") -> P | ... KT18: =IFERROR(VLOOKUP($B18,INDIRECT(KT$2&"!$C$39:$AH$63"),DAY(KT$3)+1,FALSE),"")
A19: =A18+1 -> 4 | B19: =カレンダー!B$19 -> with SAUNA(連泊) | C19: =IFERROR(VLOOKUP($B19,INDIRECT(C$2&"!$C$39:$AH$63"),DAY(C$3)+1,FALSE),"") -> Q | D19: =IFERROR(VLOOKUP($B19,INDIRECT(D$2&"!$C$39:$AH$63"),DAY(D$3)+1,FALSE),"") -> Q | E19: =IFERROR(VLOOKUP($B19,INDIRECT(E$2&"!$C$39:$AH$63"),DAY(E$3)+1,FALSE),"") -> G | F19: =IFERROR(VLOOKUP($B19,INDIRECT(F$2&"!$C$39:$AH$63"),DAY(F$3)+1,FALSE),"") -> G | G19: =IFERROR(VLOOKUP($B19,INDIRECT(G$2&"!$C$39:$AH$63"),DAY(G$3)+1,FALSE),"") -> G | H19: =IFERROR(VLOOKUP($B19,INDIRECT(H$2&"!$C$39:$AH$63"),DAY(H$3)+1,FALSE),"") -> H | I19: =IFERROR(VLOOKUP($B19,INDIRECT(I$2&"!$C$39:$AH$63"),DAY(I$3)+1,FALSE),"") -> G | J19: =IFERROR(VLOOKUP($B19,INDIRECT(J$2&"!$C$39:$AH$63"),DAY(J$3)+1,FALSE),"") -> P | ... KT19: =IFERROR(VLOOKUP($B19,INDIRECT(KT$2&"!$C$39:$AH$63"),DAY(KT$3)+1,FALSE),"")
A20: =A19+1 -> 5 | B20: =カレンダー!B$20 -> 0 | C20: =IFERROR(VLOOKUP($B20,INDIRECT(C$2&"!$C$39:$AH$63"),DAY(C$3)+1,FALSE),"") | D20: =IFERROR(VLOOKUP($B20,INDIRECT(D$2&"!$C$39:$AH$63"),DAY(D$3)+1,FALSE),"") | E20: =IFERROR(VLOOKUP($B20,INDIRECT(E$2&"!$C$39:$AH$63"),DAY(E$3)+1,FALSE),"") | F20: =IFERROR(VLOOKUP($B20,INDIRECT(F$2&"!$C$39:$AH$63"),DAY(F$3)+1,FALSE),"") | G20: =IFERROR(VLOOKUP($B20,INDIRECT(G$2&"!$C$39:$AH$63"),DAY(G$3)+1,FALSE),"") | H20: =IFERROR(VLOOKUP($B20,INDIRECT(H$2&"!$C$39:$AH$63"),DAY(H$3)+1,FALSE),"") | I20: =IFERROR(VLOOKUP($B20,INDIRECT(I$2&"!$C$39:$AH$63"),DAY(I$3)+1,FALSE),"") | J20: =IFERROR(VLOOKUP($B20,INDIRECT(J$2&"!$C$39:$AH$63"),DAY(J$3)+1,FALSE),"") | ... KT20: =IFERROR(VLOOKUP($B20,INDIRECT(KT$2&"!$C$39:$AH$63"),DAY(KT$3)+1,FALSE),"")
A21: =A20+1 -> 6 | B21: =カレンダー!B$21 -> 0 | C21: =IFERROR(VLOOKUP($B21,INDIRECT(C$2&"!$C$39:$AH$63"),DAY(C$3)+1,FALSE),"") | D21: =IFERROR(VLOOKUP($B21,INDIRECT(D$2&"!$C$39:$AH$63"),DAY(D$3)+1,FALSE),"") | E21: =IFERROR(VLOOKUP($B21,INDIRECT(E$2&"!$C$39:$AH$63"),DAY(E$3)+1,FALSE),"") | F21: =IFERROR(VLOOKUP($B21,INDIRECT(F$2&"!$C$39:$AH$63"),DAY(F$3)+1,FALSE),"") | G21: =IFERROR(VLOOKUP($B21,INDIRECT(G$2&"!$C$39:$AH$63"),DAY(G$3)+1,FALSE),"") | H21: =IFERROR(VLOOKUP($B21,INDIRECT(H$2&"!$C$39:$AH$63"),DAY(H$3)+1,FALSE),"") | I21: =IFERROR(VLOOKUP($B21,INDIRECT(I$2&"!$C$39:$AH$63"),DAY(I$3)+1,FALSE),"") | J21: =IFERROR(VLOOKUP($B21,INDIRECT(J$2&"!$C$39:$AH$63"),DAY(J$3)+1,FALSE),"") | ... KT21: =IFERROR(VLOOKUP($B21,INDIRECT(KT$2&"!$C$39:$AH$63"),DAY(KT$3)+1,FALSE),"")
A22: =A21+1 -> 7 | B22: =カレンダー!B$22 -> 0 | C22: =IFERROR(VLOOKUP($B22,INDIRECT(C$2&"!$C$39:$AH$63"),DAY(C$3)+1,FALSE),"") | D22: =IFERROR(VLOOKUP($B22,INDIRECT(D$2&"!$C$39:$AH$63"),DAY(D$3)+1,FALSE),"") | E22: =IFERROR(VLOOKUP($B22,INDIRECT(E$2&"!$C$39:$AH$63"),DAY(E$3)+1,FALSE),"") | F22: =IFERROR(VLOOKUP($B22,INDIRECT(F$2&"!$C$39:$AH$63"),DAY(F$3)+1,FALSE),"") | G22: =IFERROR(VLOOKUP($B22,INDIRECT(G$2&"!$C$39:$AH$63"),DAY(G$3)+1,FALSE),"") | H22: =IFERROR(VLOOKUP($B22,INDIRECT(H$2&"!$C$39:$AH$63"),DAY(H$3)+1,FALSE),"") | I22: =IFERROR(VLOOKUP($B22,INDIRECT(I$2&"!$C$39:$AH$63"),DAY(I$3)+1,FALSE),"") | J22: =IFERROR(VLOOKUP($B22,INDIRECT(J$2&"!$C$39:$AH$63"),DAY(J$3)+1,FALSE),"") | ... KT22: =IFERROR(VLOOKUP($B22,INDIRECT(KT$2&"!$C$39:$AH$63"),DAY(KT$3)+1,FALSE),"")
A23: =A22+1 -> 8 | B23: =カレンダー!B$23 -> 0 | C23: =IFERROR(VLOOKUP($B23,INDIRECT(C$2&"!$C$39:$AH$63"),DAY(C$3)+1,FALSE),"") | D23: =IFERROR(VLOOKUP($B23,INDIRECT(D$2&"!$C$39:$AH$63"),DAY(D$3)+1,FALSE),"") | E23: =IFERROR(VLOOKUP($B23,INDIRECT(E$2&"!$C$39:$AH$63"),DAY(E$3)+1,FALSE),"") | F23: =IFERROR(VLOOKUP($B23,INDIRECT(F$2&"!$C$39:$AH$63"),DAY(F$3)+1,FALSE),"") | G23: =IFERROR(VLOOKUP($B23,INDIRECT(G$2&"!$C$39:$AH$63"),DAY(G$3)+1,FALSE),"") | H23: =IFERROR(VLOOKUP($B23,INDIRECT(H$2&"!$C$39:$AH$63"),DAY(H$3)+1,FALSE),"") | I23: =IFERROR(VLOOKUP($B23,INDIRECT(I$2&"!$C$39:$AH$63"),DAY(I$3)+1,FALSE),"") | J23: =IFERROR(VLOOKUP($B23,INDIRECT(J$2&"!$C$39:$AH$63"),DAY(J$3)+1,FALSE),"") | ... KT23: =IFERROR(VLOOKUP($B23,INDIRECT(KT$2&"!$C$39:$AH$63"),DAY(KT$3)+1,FALSE),"")
A24: =A23+1 -> 9 | B24: =カレンダー!B$24 -> 0 | C24: =IFERROR(VLOOKUP($B24,INDIRECT(C$2&"!$C$39:$AH$63"),DAY(C$3)+1,FALSE),"") | D24: =IFERROR(VLOOKUP($B24,INDIRECT(D$2&"!$C$39:$AH$63"),DAY(D$3)+1,FALSE),"") | E24: =IFERROR(VLOOKUP($B24,INDIRECT(E$2&"!$C$39:$AH$63"),DAY(E$3)+1,FALSE),"") | F24: =IFERROR(VLOOKUP($B24,INDIRECT(F$2&"!$C$39:$AH$63"),DAY(F$3)+1,FALSE),"") | G24: =IFERROR(VLOOKUP($B24,INDIRECT(G$2&"!$C$39:$AH$63"),DAY(G$3)+1,FALSE),"") | H24: =IFERROR(VLOOKUP($B24,INDIRECT(H$2&"!$C$39:$AH$63"),DAY(H$3)+1,FALSE),"") | I24: =IFERROR(VLOOKUP($B24,INDIRECT(I$2&"!$C$39:$AH$63"),DAY(I$3)+1,FALSE),"") | J24: =IFERROR(VLOOKUP($B24,INDIRECT(J$2&"!$C$39:$AH$63"),DAY(J$3)+1,FALSE),"") | ... KT24: =IFERROR(VLOOKUP($B24,INDIRECT(KT$2&"!$C$39:$AH$63"),DAY(KT$3)+1,FALSE),"")
A25: =A24+1 -> 10 | B25: =カレンダー!B$25 -> 0 | C25: =IFERROR(VLOOKUP($B25,INDIRECT(C$2&"!$C$39:$AH$63"),DAY(C$3)+1,FALSE),"") | D25: =IFERROR(VLOOKUP($B25,INDIRECT(D$2&"!$C$39:$AH$63"),DAY(D$3)+1,FALSE),"") | E25: =IFERROR(VLOOKUP($B25,INDIRECT(E$2&"!$C$39:$AH$63"),DAY(E$3)+1,FALSE),"") | F25: =IFERROR(VLOOKUP($B25,INDIRECT(F$2&"!$C$39:$AH$63"),DAY(F$3)+1,FALSE),"") | G25: =IFERROR(VLOOKUP($B25,INDIRECT(G$2&"!$C$39:$AH$63"),DAY(G$3)+1,FALSE),"") | H25: =IFERROR(VLOOKUP($B25,INDIRECT(H$2&"!$C$39:$AH$63"),DAY(H$3)+1,FALSE),"") | I25: =IFERROR(VLOOKUP($B25,INDIRECT(I$2&"!$C$39:$AH$63"),DAY(I$3)+1,FALSE),"") | J25: =IFERROR(VLOOKUP($B25,INDIRECT(J$2&"!$C$39:$AH$63"),DAY(J$3)+1,FALSE),"") | ... KT25: =IFERROR(VLOOKUP($B25,INDIRECT(KT$2&"!$C$39:$AH$63"),DAY(KT$3)+1,FALSE),"")
A29: 1 | B29: =カレンダー!B$16 -> ラグジュアリープールヴィラ(単泊) | C29: =IFERROR(IF(VLOOKUP($B29,INDIRECT(C$2&"!$C$85:$AH$108"),DAY(C$3)+1,FALSE)="","",VLOOKUP($B29,INDIRECT(C$2&"!$C$85:$AH$108"),DAY(C$3)+1,FALSE)),"") | D29: =IFERROR(IF(VLOOKUP($B29,INDIRECT(D$2&"!$C$85:$AH$108"),DAY(D$3)+1,FALSE)="","",VLOOKUP($B29,INDIRECT(D$2&"!$C$85:$AH$108"),DAY(D$3)+1,FALSE)),"") | E29: =IFERROR(IF(VLOOKUP($B29,INDIRECT(E$2&"!$C$85:$AH$108"),DAY(E$3)+1,FALSE)="","",VLOOKUP($B29,INDIRECT(E$2&"!$C$85:$AH$108"),DAY(E$3)+1,FALSE)),"") | F29: =IFERROR(IF(VLOOKUP($B29,INDIRECT(F$2&"!$C$85:$AH$108"),DAY(F$3)+1,FALSE)="","",VLOOKUP($B29,INDIRECT(F$2&"!$C$85:$AH$108"),DAY(F$3)+1,FALSE)),"") | G29: =IFERROR(IF(VLOOKUP($B29,INDIRECT(G$2&"!$C$85:$AH$108"),DAY(G$3)+1,FALSE)="","",VLOOKUP($B29,INDIRECT(G$2&"!$C$85:$AH$108"),DAY(G$3)+1,FALSE)),"") | H29: =IFERROR(IF(VLOOKUP($B29,INDIRECT(H$2&"!$C$85:$AH$108"),DAY(H$3)+1,FALSE)="","",VLOOKUP($B29,INDIRECT(H$2&"!$C$85:$AH$108"),DAY(H$3)+1,FALSE)),"") | I29: =IFERROR(IF(VLOOKUP($B29,INDIRECT(I$2&"!$C$85:$AH$108"),DAY(I$3)+1,FALSE)="","",VLOOKUP($B29,INDIRECT(I$2&"!$C$85:$AH$108"),DAY(I$3)+1,FALSE)),"") | J29: =IFERROR(IF(VLOOKUP($B29,INDIRECT(J$2&"!$C$85:$AH$108"),DAY(J$3)+1,FALSE)="","",VLOOKUP($B29,INDIRECT(J$2&"!$C$85:$AH$108"),DAY(J$3)+1,FALSE)),"") | ... IV29: =IFERROR(IF(VLOOKUP($B29,INDIRECT(IV$2&"!$C$85:$AH$108"),DAY(IV$3)+1,FALSE)="","",VLOOKUP($B29,INDIRECT(IV$2&"!$C$85:$AH$108"),DAY(IV$3)+1,FALSE)),"")
A30: =A29+1 -> 2 | B30: =カレンダー!B$17 -> ラグジュアリープールヴィラ(連泊) | C30: =IFERROR(IF(VLOOKUP($B30,INDIRECT(C$2&"!$C$85:$AH$108"),DAY(C$3)+1,FALSE)="","",VLOOKUP($B30,INDIRECT(C$2&"!$C$85:$AH$108"),DAY(C$3)+1,FALSE)),"") | D30: =IFERROR(IF(VLOOKUP($B30,INDIRECT(D$2&"!$C$85:$AH$108"),DAY(D$3)+1,FALSE)="","",VLOOKUP($B30,INDIRECT(D$2&"!$C$85:$AH$108"),DAY(D$3)+1,FALSE)),"") | E30: =IFERROR(IF(VLOOKUP($B30,INDIRECT(E$2&"!$C$85:$AH$108"),DAY(E$3)+1,FALSE)="","",VLOOKUP($B30,INDIRECT(E$2&"!$C$85:$AH$108"),DAY(E$3)+1,FALSE)),"") | F30: =IFERROR(IF(VLOOKUP($B30,INDIRECT(F$2&"!$C$85:$AH$108"),DAY(F$3)+1,FALSE)="","",VLOOKUP($B30,INDIRECT(F$2&"!$C$85:$AH$108"),DAY(F$3)+1,FALSE)),"") | G30: =IFERROR(IF(VLOOKUP($B30,INDIRECT(G$2&"!$C$85:$AH$108"),DAY(G$3)+1,FALSE)="","",VLOOKUP($B30,INDIRECT(G$2&"!$C$85:$AH$108"),DAY(G$3)+1,FALSE)),"") | H30: =IFERROR(IF(VLOOKUP($B30,INDIRECT(H$2&"!$C$85:$AH$108"),DAY(H$3)+1,FALSE)="","",VLOOKUP($B30,INDIRECT(H$2&"!$C$85:$AH$108"),DAY(H$3)+1,FALSE)),"") | I30: =IFERROR(IF(VLOOKUP($B30,INDIRECT(I$2&"!$C$85:$AH$108"),DAY(I$3)+1,FALSE)="","",VLOOKUP($B30,INDIRECT(I$2&"!$C$85:$AH$108"),DAY(I$3)+1,FALSE)),"") | J30: =IFERROR(IF(VLOOKUP($B30,INDIRECT(J$2&"!$C$85:$AH$108"),DAY(J$3)+1,FALSE)="","",VLOOKUP($B30,INDIRECT(J$2&"!$C$85:$AH$108"),DAY(J$3)+1,FALSE)),"") | ... IV30: =IFERROR(IF(VLOOKUP($B30,INDIRECT(IV$2&"!$C$85:$AH$108"),DAY(IV$3)+1,FALSE)="","",VLOOKUP($B30,INDIRECT(IV$2&"!$C$85:$AH$108"),DAY(IV$3)+1,FALSE)),"")
A31: =A30+1 -> 3 | B31: =カレンダー!B$18 -> with SAUNA(単泊) | C31: =IFERROR(IF(VLOOKUP($B31,INDIRECT(C$2&"!$C$85:$AH$108"),DAY(C$3)+1,FALSE)="","",VLOOKUP($B31,INDIRECT(C$2&"!$C$85:$AH$108"),DAY(C$3)+1,FALSE)),"") | D31: =IFERROR(IF(VLOOKUP($B31,INDIRECT(D$2&"!$C$85:$AH$108"),DAY(D$3)+1,FALSE)="","",VLOOKUP($B31,INDIRECT(D$2&"!$C$85:$AH$108"),DAY(D$3)+1,FALSE)),"") | E31: =IFERROR(IF(VLOOKUP($B31,INDIRECT(E$2&"!$C$85:$AH$108"),DAY(E$3)+1,FALSE)="","",VLOOKUP($B31,INDIRECT(E$2&"!$C$85:$AH$108"),DAY(E$3)+1,FALSE)),"") | F31: =IFERROR(IF(VLOOKUP($B31,INDIRECT(F$2&"!$C$85:$AH$108"),DAY(F$3)+1,FALSE)="","",VLOOKUP($B31,INDIRECT(F$2&"!$C$85:$AH$108"),DAY(F$3)+1,FALSE)),"") | G31: =IFERROR(IF(VLOOKUP($B31,INDIRECT(G$2&"!$C$85:$AH$108"),DAY(G$3)+1,FALSE)="","",VLOOKUP($B31,INDIRECT(G$2&"!$C$85:$AH$108"),DAY(G$3)+1,FALSE)),"") | H31: =IFERROR(IF(VLOOKUP($B31,INDIRECT(H$2&"!$C$85:$AH$108"),DAY(H$3)+1,FALSE)="","",VLOOKUP($B31,INDIRECT(H$2&"!$C$85:$AH$108"),DAY(H$3)+1,FALSE)),"") | I31: =IFERROR(IF(VLOOKUP($B31,INDIRECT(I$2&"!$C$85:$AH$108"),DAY(I$3)+1,FALSE)="","",VLOOKUP($B31,INDIRECT(I$2&"!$C$85:$AH$108"),DAY(I$3)+1,FALSE)),"") | J31: =IFERROR(IF(VLOOKUP($B31,INDIRECT(J$2&"!$C$85:$AH$108"),DAY(J$3)+1,FALSE)="","",VLOOKUP($B31,INDIRECT(J$2&"!$C$85:$AH$108"),DAY(J$3)+1,FALSE)),"") | ... IV31: =IFERROR(IF(VLOOKUP($B31,INDIRECT(IV$2&"!$C$85:$AH$108"),DAY(IV$3)+1,FALSE)="","",VLOOKUP($B31,INDIRECT(IV$2&"!$C$85:$AH$108"),DAY(IV$3)+1,FALSE)),"")
A32: =A31+1 -> 4 | B32: =カレンダー!B$19 -> with SAUNA(連泊) | C32: =IFERROR(IF(VLOOKUP($B32,INDIRECT(C$2&"!$C$85:$AH$108"),DAY(C$3)+1,FALSE)="","",VLOOKUP($B32,INDIRECT(C$2&"!$C$85:$AH$108"),DAY(C$3)+1,FALSE)),"") | D32: =IFERROR(IF(VLOOKUP($B32,INDIRECT(D$2&"!$C$85:$AH$108"),DAY(D$3)+1,FALSE)="","",VLOOKUP($B32,INDIRECT(D$2&"!$C$85:$AH$108"),DAY(D$3)+1,FALSE)),"") | E32: =IFERROR(IF(VLOOKUP($B32,INDIRECT(E$2&"!$C$85:$AH$108"),DAY(E$3)+1,FALSE)="","",VLOOKUP($B32,INDIRECT(E$2&"!$C$85:$AH$108"),DAY(E$3)+1,FALSE)),"") | F32: =IFERROR(IF(VLOOKUP($B32,INDIRECT(F$2&"!$C$85:$AH$108"),DAY(F$3)+1,FALSE)="","",VLOOKUP($B32,INDIRECT(F$2&"!$C$85:$AH$108"),DAY(F$3)+1,FALSE)),"") | G32: =IFERROR(IF(VLOOKUP($B32,INDIRECT(G$2&"!$C$85:$AH$108"),DAY(G$3)+1,FALSE)="","",VLOOKUP($B32,INDIRECT(G$2&"!$C$85:$AH$108"),DAY(G$3)+1,FALSE)),"") | H32: =IFERROR(IF(VLOOKUP($B32,INDIRECT(H$2&"!$C$85:$AH$108"),DAY(H$3)+1,FALSE)="","",VLOOKUP($B32,INDIRECT(H$2&"!$C$85:$AH$108"),DAY(H$3)+1,FALSE)),"") | I32: =IFERROR(IF(VLOOKUP($B32,INDIRECT(I$2&"!$C$85:$AH$108"),DAY(I$3)+1,FALSE)="","",VLOOKUP($B32,INDIRECT(I$2&"!$C$85:$AH$108"),DAY(I$3)+1,FALSE)),"") | J32: =IFERROR(IF(VLOOKUP($B32,INDIRECT(J$2&"!$C$85:$AH$108"),DAY(J$3)+1,FALSE)="","",VLOOKUP($B32,INDIRECT(J$2&"!$C$85:$AH$108"),DAY(J$3)+1,FALSE)),"") | ... IV32: =IFERROR(IF(VLOOKUP($B32,INDIRECT(IV$2&"!$C$85:$AH$108"),DAY(IV$3)+1,FALSE)="","",VLOOKUP($B32,INDIRECT(IV$2&"!$C$85:$AH$108"),DAY(IV$3)+1,FALSE)),"")
A33: =A32+1 -> 5 | B33: =カレンダー!B$20 -> 0 | C33: =IFERROR(IF(VLOOKUP($B33,INDIRECT(C$2&"!$C$85:$AH$108"),DAY(C$3)+1,FALSE)="","",VLOOKUP($B33,INDIRECT(C$2&"!$C$85:$AH$108"),DAY(C$3)+1,FALSE)),"") | D33: =IFERROR(IF(VLOOKUP($B33,INDIRECT(D$2&"!$C$85:$AH$108"),DAY(D$3)+1,FALSE)="","",VLOOKUP($B33,INDIRECT(D$2&"!$C$85:$AH$108"),DAY(D$3)+1,FALSE)),"") | E33: =IFERROR(IF(VLOOKUP($B33,INDIRECT(E$2&"!$C$85:$AH$108"),DAY(E$3)+1,FALSE)="","",VLOOKUP($B33,INDIRECT(E$2&"!$C$85:$AH$108"),DAY(E$3)+1,FALSE)),"") | F33: =IFERROR(IF(VLOOKUP($B33,INDIRECT(F$2&"!$C$85:$AH$108"),DAY(F$3)+1,FALSE)="","",VLOOKUP($B33,INDIRECT(F$2&"!$C$85:$AH$108"),DAY(F$3)+1,FALSE)),"") | G33: =IFERROR(IF(VLOOKUP($B33,INDIRECT(G$2&"!$C$85:$AH$108"),DAY(G$3)+1,FALSE)="","",VLOOKUP($B33,INDIRECT(G$2&"!$C$85:$AH$108"),DAY(G$3)+1,FALSE)),"") | H33: =IFERROR(IF(VLOOKUP($B33,INDIRECT(H$2&"!$C$85:$AH$108"),DAY(H$3)+1,FALSE)="","",VLOOKUP($B33,INDIRECT(H$2&"!$C$85:$AH$108"),DAY(H$3)+1,FALSE)),"") | I33: =IFERROR(IF(VLOOKUP($B33,INDIRECT(I$2&"!$C$85:$AH$108"),DAY(I$3)+1,FALSE)="","",VLOOKUP($B33,INDIRECT(I$2&"!$C$85:$AH$108"),DAY(I$3)+1,FALSE)),"") | J33: =IFERROR(IF(VLOOKUP($B33,INDIRECT(J$2&"!$C$85:$AH$108"),DAY(J$3)+1,FALSE)="","",VLOOKUP($B33,INDIRECT(J$2&"!$C$85:$AH$108"),DAY(J$3)+1,FALSE)),"") | ... IV33: =IFERROR(IF(VLOOKUP($B33,INDIRECT(IV$2&"!$C$85:$AH$108"),DAY(IV$3)+1,FALSE)="","",VLOOKUP($B33,INDIRECT(IV$2&"!$C$85:$AH$108"),DAY(IV$3)+1,FALSE)),"")
A34: =A33+1 -> 6 | B34: =カレンダー!B$21 -> 0 | C34: =IFERROR(IF(VLOOKUP($B34,INDIRECT(C$2&"!$C$85:$AH$108"),DAY(C$3)+1,FALSE)="","",VLOOKUP($B34,INDIRECT(C$2&"!$C$85:$AH$108"),DAY(C$3)+1,FALSE)),"") | D34: =IFERROR(IF(VLOOKUP($B34,INDIRECT(D$2&"!$C$85:$AH$108"),DAY(D$3)+1,FALSE)="","",VLOOKUP($B34,INDIRECT(D$2&"!$C$85:$AH$108"),DAY(D$3)+1,FALSE)),"") | E34: =IFERROR(IF(VLOOKUP($B34,INDIRECT(E$2&"!$C$85:$AH$108"),DAY(E$3)+1,FALSE)="","",VLOOKUP($B34,INDIRECT(E$2&"!$C$85:$AH$108"),DAY(E$3)+1,FALSE)),"") | F34: =IFERROR(IF(VLOOKUP($B34,INDIRECT(F$2&"!$C$85:$AH$108"),DAY(F$3)+1,FALSE)="","",VLOOKUP($B34,INDIRECT(F$2&"!$C$85:$AH$108"),DAY(F$3)+1,FALSE)),"") | G34: =IFERROR(IF(VLOOKUP($B34,INDIRECT(G$2&"!$C$85:$AH$108"),DAY(G$3)+1,FALSE)="","",VLOOKUP($B34,INDIRECT(G$2&"!$C$85:$AH$108"),DAY(G$3)+1,FALSE)),"") | H34: =IFERROR(IF(VLOOKUP($B34,INDIRECT(H$2&"!$C$85:$AH$108"),DAY(H$3)+1,FALSE)="","",VLOOKUP($B34,INDIRECT(H$2&"!$C$85:$AH$108"),DAY(H$3)+1,FALSE)),"") | I34: =IFERROR(IF(VLOOKUP($B34,INDIRECT(I$2&"!$C$85:$AH$108"),DAY(I$3)+1,FALSE)="","",VLOOKUP($B34,INDIRECT(I$2&"!$C$85:$AH$108"),DAY(I$3)+1,FALSE)),"") | J34: =IFERROR(IF(VLOOKUP($B34,INDIRECT(J$2&"!$C$85:$AH$108"),DAY(J$3)+1,FALSE)="","",VLOOKUP($B34,INDIRECT(J$2&"!$C$85:$AH$108"),DAY(J$3)+1,FALSE)),"") | ... IV34: =IFERROR(IF(VLOOKUP($B34,INDIRECT(IV$2&"!$C$85:$AH$108"),DAY(IV$3)+1,FALSE)="","",VLOOKUP($B34,INDIRECT(IV$2&"!$C$85:$AH$108"),DAY(IV$3)+1,FALSE)),"")
A35: =A34+1 -> 7 | B35: =カレンダー!B$22 -> 0 | C35: =IFERROR(IF(VLOOKUP($B35,INDIRECT(C$2&"!$C$85:$AH$108"),DAY(C$3)+1,FALSE)="","",VLOOKUP($B35,INDIRECT(C$2&"!$C$85:$AH$108"),DAY(C$3)+1,FALSE)),"") | D35: =IFERROR(IF(VLOOKUP($B35,INDIRECT(D$2&"!$C$85:$AH$108"),DAY(D$3)+1,FALSE)="","",VLOOKUP($B35,INDIRECT(D$2&"!$C$85:$AH$108"),DAY(D$3)+1,FALSE)),"") | E35: =IFERROR(IF(VLOOKUP($B35,INDIRECT(E$2&"!$C$85:$AH$108"),DAY(E$3)+1,FALSE)="","",VLOOKUP($B35,INDIRECT(E$2&"!$C$85:$AH$108"),DAY(E$3)+1,FALSE)),"") | F35: =IFERROR(IF(VLOOKUP($B35,INDIRECT(F$2&"!$C$85:$AH$108"),DAY(F$3)+1,FALSE)="","",VLOOKUP($B35,INDIRECT(F$2&"!$C$85:$AH$108"),DAY(F$3)+1,FALSE)),"") | G35: =IFERROR(IF(VLOOKUP($B35,INDIRECT(G$2&"!$C$85:$AH$108"),DAY(G$3)+1,FALSE)="","",VLOOKUP($B35,INDIRECT(G$2&"!$C$85:$AH$108"),DAY(G$3)+1,FALSE)),"") | H35: =IFERROR(IF(VLOOKUP($B35,INDIRECT(H$2&"!$C$85:$AH$108"),DAY(H$3)+1,FALSE)="","",VLOOKUP($B35,INDIRECT(H$2&"!$C$85:$AH$108"),DAY(H$3)+1,FALSE)),"") | I35: =IFERROR(IF(VLOOKUP($B35,INDIRECT(I$2&"!$C$85:$AH$108"),DAY(I$3)+1,FALSE)="","",VLOOKUP($B35,INDIRECT(I$2&"!$C$85:$AH$108"),DAY(I$3)+1,FALSE)),"") | J35: =IFERROR(IF(VLOOKUP($B35,INDIRECT(J$2&"!$C$85:$AH$108"),DAY(J$3)+1,FALSE)="","",VLOOKUP($B35,INDIRECT(J$2&"!$C$85:$AH$108"),DAY(J$3)+1,FALSE)),"") | ... IV35: =IFERROR(IF(VLOOKUP($B35,INDIRECT(IV$2&"!$C$85:$AH$108"),DAY(IV$3)+1,FALSE)="","",VLOOKUP($B35,INDIRECT(IV$2&"!$C$85:$AH$108"),DAY(IV$3)+1,FALSE)),"")
A36: =A35+1 -> 8 | B36: =カレンダー!B$23 -> 0 | C36: =IFERROR(IF(VLOOKUP($B36,INDIRECT(C$2&"!$C$85:$AH$108"),DAY(C$3)+1,FALSE)="","",VLOOKUP($B36,INDIRECT(C$2&"!$C$85:$AH$108"),DAY(C$3)+1,FALSE)),"") | D36: =IFERROR(IF(VLOOKUP($B36,INDIRECT(D$2&"!$C$85:$AH$108"),DAY(D$3)+1,FALSE)="","",VLOOKUP($B36,INDIRECT(D$2&"!$C$85:$AH$108"),DAY(D$3)+1,FALSE)),"") | E36: =IFERROR(IF(VLOOKUP($B36,INDIRECT(E$2&"!$C$85:$AH$108"),DAY(E$3)+1,FALSE)="","",VLOOKUP($B36,INDIRECT(E$2&"!$C$85:$AH$108"),DAY(E$3)+1,FALSE)),"") | F36: =IFERROR(IF(VLOOKUP($B36,INDIRECT(F$2&"!$C$85:$AH$108"),DAY(F$3)+1,FALSE)="","",VLOOKUP($B36,INDIRECT(F$2&"!$C$85:$AH$108"),DAY(F$3)+1,FALSE)),"") | G36: =IFERROR(IF(VLOOKUP($B36,INDIRECT(G$2&"!$C$85:$AH$108"),DAY(G$3)+1,FALSE)="","",VLOOKUP($B36,INDIRECT(G$2&"!$C$85:$AH$108"),DAY(G$3)+1,FALSE)),"") | H36: =IFERROR(IF(VLOOKUP($B36,INDIRECT(H$2&"!$C$85:$AH$108"),DAY(H$3)+1,FALSE)="","",VLOOKUP($B36,INDIRECT(H$2&"!$C$85:$AH$108"),DAY(H$3)+1,FALSE)),"") | I36: =IFERROR(IF(VLOOKUP($B36,INDIRECT(I$2&"!$C$85:$AH$108"),DAY(I$3)+1,FALSE)="","",VLOOKUP($B36,INDIRECT(I$2&"!$C$85:$AH$108"),DAY(I$3)+1,FALSE)),"") | J36: =IFERROR(IF(VLOOKUP($B36,INDIRECT(J$2&"!$C$85:$AH$108"),DAY(J$3)+1,FALSE)="","",VLOOKUP($B36,INDIRECT(J$2&"!$C$85:$AH$108"),DAY(J$3)+1,FALSE)),"") | ... IV36: =IFERROR(IF(VLOOKUP($B36,INDIRECT(IV$2&"!$C$85:$AH$108"),DAY(IV$3)+1,FALSE)="","",VLOOKUP($B36,INDIRECT(IV$2&"!$C$85:$AH$108"),DAY(IV$3)+1,FALSE)),"")
A37: =A36+1 -> 9 | B37: =カレンダー!B$24 -> 0 | C37: =IFERROR(IF(VLOOKUP($B37,INDIRECT(C$2&"!$C$85:$AH$108"),DAY(C$3)+1,FALSE)="","",VLOOKUP($B37,INDIRECT(C$2&"!$C$85:$AH$108"),DAY(C$3)+1,FALSE)),"") | D37: =IFERROR(IF(VLOOKUP($B37,INDIRECT(D$2&"!$C$85:$AH$108"),DAY(D$3)+1,FALSE)="","",VLOOKUP($B37,INDIRECT(D$2&"!$C$85:$AH$108"),DAY(D$3)+1,FALSE)),"") | E37: =IFERROR(IF(VLOOKUP($B37,INDIRECT(E$2&"!$C$85:$AH$108"),DAY(E$3)+1,FALSE)="","",VLOOKUP($B37,INDIRECT(E$2&"!$C$85:$AH$108"),DAY(E$3)+1,FALSE)),"") | F37: =IFERROR(IF(VLOOKUP($B37,INDIRECT(F$2&"!$C$85:$AH$108"),DAY(F$3)+1,FALSE)="","",VLOOKUP($B37,INDIRECT(F$2&"!$C$85:$AH$108"),DAY(F$3)+1,FALSE)),"") | G37: =IFERROR(IF(VLOOKUP($B37,INDIRECT(G$2&"!$C$85:$AH$108"),DAY(G$3)+1,FALSE)="","",VLOOKUP($B37,INDIRECT(G$2&"!$C$85:$AH$108"),DAY(G$3)+1,FALSE)),"") | H37: =IFERROR(IF(VLOOKUP($B37,INDIRECT(H$2&"!$C$85:$AH$108"),DAY(H$3)+1,FALSE)="","",VLOOKUP($B37,INDIRECT(H$2&"!$C$85:$AH$108"),DAY(H$3)+1,FALSE)),"") | I37: =IFERROR(IF(VLOOKUP($B37,INDIRECT(I$2&"!$C$85:$AH$108"),DAY(I$3)+1,FALSE)="","",VLOOKUP($B37,INDIRECT(I$2&"!$C$85:$AH$108"),DAY(I$3)+1,FALSE)),"") | J37: =IFERROR(IF(VLOOKUP($B37,INDIRECT(J$2&"!$C$85:$AH$108"),DAY(J$3)+1,FALSE)="","",VLOOKUP($B37,INDIRECT(J$2&"!$C$85:$AH$108"),DAY(J$3)+1,FALSE)),"") | ... IV37: =IFERROR(IF(VLOOKUP($B37,INDIRECT(IV$2&"!$C$85:$AH$108"),DAY(IV$3)+1,FALSE)="","",VLOOKUP($B37,INDIRECT(IV$2&"!$C$85:$AH$108"),DAY(IV$3)+1,FALSE)),"")
A38: =A37+1 -> 10 | B38: =カレンダー!B$25 -> 0 | C38: =IFERROR(IF(VLOOKUP($B38,INDIRECT(C$2&"!$C$85:$AH$108"),DAY(C$3)+1,FALSE)="","",VLOOKUP($B38,INDIRECT(C$2&"!$C$85:$AH$108"),DAY(C$3)+1,FALSE)),"") | D38: =IFERROR(IF(VLOOKUP($B38,INDIRECT(D$2&"!$C$85:$AH$108"),DAY(D$3)+1,FALSE)="","",VLOOKUP($B38,INDIRECT(D$2&"!$C$85:$AH$108"),DAY(D$3)+1,FALSE)),"") | E38: =IFERROR(IF(VLOOKUP($B38,INDIRECT(E$2&"!$C$85:$AH$108"),DAY(E$3)+1,FALSE)="","",VLOOKUP($B38,INDIRECT(E$2&"!$C$85:$AH$108"),DAY(E$3)+1,FALSE)),"") | F38: =IFERROR(IF(VLOOKUP($B38,INDIRECT(F$2&"!$C$85:$AH$108"),DAY(F$3)+1,FALSE)="","",VLOOKUP($B38,INDIRECT(F$2&"!$C$85:$AH$108"),DAY(F$3)+1,FALSE)),"") | G38: =IFERROR(IF(VLOOKUP($B38,INDIRECT(G$2&"!$C$85:$AH$108"),DAY(G$3)+1,FALSE)="","",VLOOKUP($B38,INDIRECT(G$2&"!$C$85:$AH$108"),DAY(G$3)+1,FALSE)),"") | H38: =IFERROR(IF(VLOOKUP($B38,INDIRECT(H$2&"!$C$85:$AH$108"),DAY(H$3)+1,FALSE)="","",VLOOKUP($B38,INDIRECT(H$2&"!$C$85:$AH$108"),DAY(H$3)+1,FALSE)),"") | I38: =IFERROR(IF(VLOOKUP($B38,INDIRECT(I$2&"!$C$85:$AH$108"),DAY(I$3)+1,FALSE)="","",VLOOKUP($B38,INDIRECT(I$2&"!$C$85:$AH$108"),DAY(I$3)+1,FALSE)),"") | J38: =IFERROR(IF(VLOOKUP($B38,INDIRECT(J$2&"!$C$85:$AH$108"),DAY(J$3)+1,FALSE)="","",VLOOKUP($B38,INDIRECT(J$2&"!$C$85:$AH$108"),DAY(J$3)+1,FALSE)),"") | ... IV38: =IFERROR(IF(VLOOKUP($B38,INDIRECT(IV$2&"!$C$85:$AH$108"),DAY(IV$3)+1,FALSE)="","",VLOOKUP($B38,INDIRECT(IV$2&"!$C$85:$AH$108"),DAY(IV$3)+1,FALSE)),"")
B40: ラグジュアリープールヴィラ(単泊) | AZ40: E | BA40: T | BB40: N | BC40: N | BD40: N | BE40: N | BF40: K | BG40: L | BH40: Q | BI40: O | BJ40: H | BK40: L | BL40: L | BM40: Q | BN40: R | BO40: V | BP40: U | BQ40: O | BR40: Q | BS40: O | BT40: M | BU40: Q | BV40: W | BW40: V | BX40: L | BY40: L | BZ40: H | CA40: I | CB40: M | CC40: M | CD40: J | CE40: K | CF40: J | CG40: K | CH40: G | CI40: U | CJ40: V | CK40: S | CL40: G | CM40: G | CN40: D | CO40: I | CP40: I | CQ40: Q | CR40: Q | CS40: O | CT40: H | CU40: H | CV40: H | CW40: I | CX40: M | CY40: J | CZ40: J | DA40: J | DB40: C | DC40: C | DD40: M | DE40: M | DF40: C | DG40: C | DH40: C | DI40: C | DJ40: C | DK40: K | DL40: N | DM40: L | DN40: N | DO40: C | DP40: C | DQ40: C | DR40: G | DS40: I | DT40: C | DU40: C | DV40: C | DW40: D | DX40: D | DY40: G | DZ40: I | EA40: C | EB40: C | EC40: C | ED40: C | EE40: C | EF40: G | EG40: I | EH40: C | EI40: C | EJ40: C | EK40: C | EL40: C | EM40: G | EN40: I | EO40: G | EP40: G | EQ40: G | ER40: G | ES40: I | ET40: T | EU40: T | EV40: T | EW40: T | EX40: X | EY40: Z | EZ40: Y | FA40: W | FB40: T | FC40: C | FD40: C | FE40: C | FF40: C | FG40: C | FH40: G | FI40: I | FJ40: I | FK40: C | FL40: C | FM40: C | FN40: C | FO40: G | FP40: I | FQ40: C | FR40: C | FS40: C | FT40: C | FU40: C | FV40: G | FW40: I | FX40: C | FY40: C | FZ40: C | GA40: C | GB40: C | GC40: G | GD40: I
B41: ラグジュアリープールヴィラ(連泊) | AZ41: E | BA41: T | BB41: N | BC41: N | BD41: N | BE41: N | BF41: K | BG41: L | BH41: Q | BI41: O | BJ41: H | BK41: L | BL41: L | BM41: Q | BN41: R | BO41: V | BP41: U | BQ41: O | BR41: Q | BS41: O | BT41: M | BU41: Q | BV41: W | BW41: V | BX41: L | BY41: L | BZ41: H | CA41: I | CB41: M | CC41: M | CD41: J | CE41: K | CF41: J | CG41: K | CH41: G | CI41: U | CJ41: V | CK41: S | CL41: G | CM41: G | CN41: D | CO41: I | CP41: I | CQ41: Q | CR41: Q | CS41: O | CT41: H | CU41: H | CV41: H | CW41: I | CX41: M | CY41: J | CZ41: J | DA41: J | DB41: C | DC41: C | DD41: M | DE41: M | DF41: C | DG41: C | DH41: C | DI41: C | DJ41: C | DK41: K | DL41: N | DM41: L | DN41: N | DO41: C | DP41: C | DQ41: C | DR41: G | DS41: I | DT41: C | DU41: C | DV41: C | DW41: D | DX41: D | DY41: G | DZ41: I | EA41: C | EB41: C | EC41: C | ED41: C | EE41: C | EF41: G | EG41: I | EH41: C | EI41: C | EJ41: C | EK41: C | EL41: C | EM41: G | EN41: I | EO41: G | EP41: G | EQ41: G | ER41: G | ES41: I | ET41: T | EU41: T | EV41: T | EW41: T | EX41: X | EY41: Z | EZ41: Y | FA41: W | FB41: T | FC41: C | FD41: C | FE41: C | FF41: C | FG41: C | FH41: G | FI41: I | FJ41: I | FK41: C | FL41: C | FM41: C | FN41: C | FO41: G | FP41: I | FQ41: C | FR41: C | FS41: C | FT41: C | FU41: C | FV41: G | FW41: I | FX41: C | FY41: C | FZ41: C | GA41: C | GB41: C | GC41: G | GD41: I
B42: with SAUNA(単泊) | AZ42: E | BA42: T | BB42: N | BC42: N | BD42: N | BE42: N | BF42: K | BG42: L | BH42: Q | BI42: O | BJ42: H | BK42: L | BL42: L | BM42: Q | BN42: R | BO42: V | BP42: U | BQ42: O | BR42: Q | BS42: O | BT42: M | BU42: Q | BV42: W | BW42: V | BX42: L | BY42: L | BZ42: H | CA42: I | CB42: M | CC42: M | CD42: J | CE42: K | CF42: J | CG42: K | CH42: G | CI42: U | CJ42: V | CK42: S | CL42: G | CM42: G | CN42: D | CO42: I | CP42: I | CQ42: Q | CR42: Q | CS42: O | CT42: H | CU42: H | CV42: H | CW42: I | CX42: M | CY42: J | CZ42: J | DA42: J | DB42: C | DC42: C | DD42: M | DE42: M | DF42: C | DG42: C | DH42: C | DI42: C | DJ42: C | DK42: K | DL42: N | DM42: L | DN42: N | DO42: C | DP42: C | DQ42: C | DR42: G | DS42: I | DT42: C | DU42: C | DV42: C | DW42: D | DX42: D | DY42: G | DZ42: I | EA42: C | EB42: C | EC42: C | ED42: C | EE42: C | EF42: G | EG42: I | EH42: C | EI42: C | EJ42: C | EK42: C | EL42: C | EM42: G | EN42: I | EO42: G | EP42: G | EQ42: G | ER42: G | ES42: I | ET42: T | EU42: T | EV42: T | EW42: T | EX42: X | EY42: Z | EZ42: Y | FA42: W | FB42: T | FC42: C | FD42: C | FE42: C | FF42: C | FG42: C | FH42: G | FI42: I | FJ42: I | FK42: C | FL42: C | FM42: C | FN42: C | FO42: G | FP42: I | FQ42: C | FR42: C | FS42: C | FT42: C | FU42: C | FV42: G | FW42: I | FX42: C | FY42: C | FZ42: C | GA42: C | GB42: C | GC42: G | GD42: I
B43: with SAUNA(連泊) | AZ43: E | BA43: T | BB43: N | BC43: N | BD43: N | BE43: N | BF43: K | BG43: L | BH43: Q | BI43: O | BJ43: H | BK43: L | BL43: L | BM43: Q | BN43: R | BO43: V | BP43: U | BQ43: O | BR43: Q | BS43: O | BT43: M | BU43: Q | BV43: W | BW43: V | BX43: L | BY43: L | BZ43: H | CA43: I | CB43: M | CC43: M | CD43: J | CE43: K | CF43: J | CG43: K | CH43: G | CI43: U | CJ43: V | CK43: S | CL43: G | CM43: G | CN43: D | CO43: I | CP43: I | CQ43: Q | CR43: Q | CS43: O | CT43: H | CU43: H | CV43: H | CW43: I | CX43: M | CY43: J | CZ43: J | DA43: J | DB43: C | DC43: C | DD43: M | DE43: M | DF43: C | DG43: C | DH43: C | DI43: C | DJ43: C | DK43: K | DL43: N | DM43: L | DN43: N | DO43: C | DP43: C | DQ43: C | DR43: G | DS43: I | DT43: C | DU43: C | DV43: C | DW43: D | DX43: D | DY43: G | DZ43: I | EA43: C | EB43: C | EC43: C | ED43: C | EE43: C | EF43: G | EG43: I | EH43: C | EI43: C | EJ43: C | EK43: C | EL43: C | EM43: G | EN43: I | EO43: G | EP43: G | EQ43: G | ER43: G | ES43: I | ET43: T | EU43: T | EV43: T | EW43: T | EX43: X | EY43: Z | EZ43: Y | FA43: W | FB43: T | FC43: C | FD43: C | FE43: C | FF43: C | FG43: C | FH43: G | FI43: I | FJ43: I | FK43: C | FL43: C | FM43: C | FN43: C | FO43: G | FP43: I | FQ43: C | FR43: C | FS43: C | FT43: C | FU43: C | FV43: G | FW43: I | FX43: C | FY43: C | FZ43: C | GA43: C | GB43: C | GC43: G | GD43: I
A45: =SUM(C45:IV45) -> -130 | B45: ラグジュアリープールヴィラ(単泊) | C45: =IF(ISBLANK(C40),"",IF(C40=C4,0,-1)) | D45: =IF(ISBLANK(D40),"",IF(D40=D4,0,-1)) | E45: =IF(ISBLANK(E40),"",IF(E40=E4,0,-1)) | F45: =IF(ISBLANK(F40),"",IF(F40=F4,0,-1)) | G45: =IF(ISBLANK(G40),"",IF(G40=G4,0,-1)) | H45: =IF(ISBLANK(H40),"",IF(H40=H4,0,-1)) | I45: =IF(ISBLANK(I40),"",IF(I40=I4,0,-1)) | J45: =IF(ISBLANK(J40),"",IF(J40=J4,0,-1)) | ... IV45: =IF(ISBLANK(IV40),"",IF(IV40=IV4,0,-1))
A46: =SUM(C46:IV46) -> -130 | B46: ラグジュアリープールヴィラ(連泊) | C46: =IF(ISBLANK(C41),"",IF(C41=C5,0,-1)) | D46: =IF(ISBLANK(D41),"",IF(D41=D5,0,-1)) | E46: =IF(ISBLANK(E41),"",IF(E41=E5,0,-1)) | F46: =IF(ISBLANK(F41),"",IF(F41=F5,0,-1)) | G46: =IF(ISBLANK(G41),"",IF(G41=G5,0,-1)) | H46: =IF(ISBLANK(H41),"",IF(H41=H5,0,-1)) | I46: =IF(ISBLANK(I41),"",IF(I41=I5,0,-1)) | J46: =IF(ISBLANK(J41),"",IF(J41=J5,0,-1)) | ... IV46: =IF(ISBLANK(IV41),"",IF(IV41=IV5,0,-1))
A47: =SUM(C47:IV47) -> -130 | B47: with SAUNA(単泊) | C47: =IF(ISBLANK(C42),"",IF(C42=C6,0,-1)) | D47: =IF(ISBLANK(D42),"",IF(D42=D6,0,-1)) | E47: =IF(ISBLANK(E42),"",IF(E42=E6,0,-1)) | F47: =IF(ISBLANK(F42),"",IF(F42=F6,0,-1)) | G47: =IF(ISBLANK(G42),"",IF(G42=G6,0,-1)) | H47: =IF(ISBLANK(H42),"",IF(H42=H6,0,-1)) | I47: =IF(ISBLANK(I42),"",IF(I42=I6,0,-1)) | J47: =IF(ISBLANK(J42),"",IF(J42=J6,0,-1)) | ... IV47: =IF(ISBLANK(IV42),"",IF(IV42=IV6,0,-1))
...

Sheet カレンダー
B1: 45870 | C1: =B1-1 -> 45869 | D1: 料金プラン①⇒ | F1: WEB割 | I1: 割引率⇒
B2: カレンダー名 | C2: 利用人数⇩ | D2: A | E2: B | F2: C | G2: D | H2: E | I2: F | J2: G | K2: H | L2: I | M2: J | N2: K | O2: L | P2: M | Q2: N | R2: O | S2: P | T2: Q | U2: R | V2: S | W2: T | X2: U | Y2: V | Z2: W | AA2: X | AB2: Y | AC2: Z
A3: 1 | B3: ラグジュアリープールヴィラ | C3: 2
A4: 12 | B4: with SAUNA | C4: 2
A5: 6 | C5: 2
A6: 13 | C6: 2
A7: 8 | C7: 1
A8: 14 | C8: 4
C10: =TEXT(EDATE(B1,0),"yyyy年m月") -> 2025年8月 | K10: =TEXT(EDATE(C10,1),"yyyy年m月") -> 2025年9月 | S10: =TEXT(EDATE(K10,1),"yyyy年m月") -> 2025年10月
B11: ⇩対象部屋タイプ⇩ | C11: 日 | D11: 月 | E11: 火 | F11: 水 | G11: 木 | H11: 金 | I11: 土 | K11: 日 | L11: 月 | M11: 火 | N11: 水 | O11: 木 | P11: 金 | Q11: 土 | S11: 日 | T11: 月 | U11: 火 | V11: 水 | W11: 木 | X11: 金 | Y11: 土
C12: =$C$10-WEEKDAY($C$10)+1 -> 45865 | D12: =$C$10-WEEKDAY($C$10)+2 -> 45866 | E12: =$C$10-WEEKDAY($C$10)+3 -> 45867 | F12: =$C$10-WEEKDAY($C$10)+4 -> 45868 | G12: =$C$10-WEEKDAY($C$10)+5 -> 45869 | H12: =$C$10-WEEKDAY($C$10)+6 -> 45870 | I12: =$C$10-WEEKDAY($C$10)+7 -> 45871 | K12: =$K$10-WEEKDAY($K$10)+1 -> 45900 | L12: =$K$10-WEEKDAY($K$10)+2 -> 45901 | M12: =$K$10-WEEKDAY($K$10)+3 -> 45902 | N12: =$K$10-WEEKDAY($K$10)+4 -> 45903 | O12: =$K$10-WEEKDAY($K$10)+5 -> 45904 | P12: =$K$10-WEEKDAY($K$10)+6 -> 45905 | Q12: =$K$10-WEEKDAY($K$10)+7 -> 45906 | S12: =$S$10-WEEKDAY($S$10)+1 -> 45928 | T12: =$S$10-WEEKDAY($S$10)+2 -> 45929 | U12: =$S$10-WEEKDAY($S$10)+3 -> 45930 | V12: =$S$10-WEEKDAY($S$10)+4 -> 45931 | W12: =$S$10-WEEKDAY($S$10)+5 -> 45932 | X12: =$S$10-WEEKDAY($S$10)+6 -> 45933 | Y12: =$S$10-WEEKDAY($S$10)+7 -> 45934
B13: ラグジュアリープールヴィラ(連泊) | C13: =IF(TEXT(カレンダー!C12,"yyyy年m月")=TEXT($C$10,"yyyy年m月"),INDEX(横カレンダー!$C$4:$IV$13,MATCH($B$13,横カレンダー!$B$4:$B$13,0),MATCH(カレンダー!C12,横カレンダー!$C$3:$IV$3,0)),"") | D13: =IF(TEXT(カレンダー!D12,"yyyy年m月")=TEXT($C$10,"yyyy年m月"),INDEX(横カレンダー!$C$4:$IV$13,MATCH($B$13,横カレンダー!$B$4:$B$13,0),MATCH(カレンダー!D12,横カレンダー!$C$3:$IV$3,0)),"") | E13: =IF(TEXT(カレンダー!E12,"yyyy年m月")=TEXT($C$10,"yyyy年m月"),INDEX(横カレンダー!$C$4:$IV$13,MATCH($B$13,横カレンダー!$B$4:$B$13,0),MATCH(カレンダー!E12,横カレンダー!$C$3:$IV$3,0)),"") | F13: =IF(TEXT(カレンダー!F12,"yyyy年m月")=TEXT($C$10,"yyyy年m月"),INDEX(横カレンダー!$C$4:$IV$13,MATCH($B$13,横カレンダー!$B$4:$B$13,0),MATCH(カレンダー!F12,横カレンダー!$C$3:$IV$3,0)),"") | G13: =IF(TEXT(カレンダー!G12,"yyyy年m月")=TEXT($C$10,"yyyy年m月"),INDEX(横カレンダー!$C$4:$IV$13,MATCH($B$13,横カレンダー!$B$4:$B$13,0),MATCH(カレンダー!G12,横カレンダー!$C$3:$IV$3,0)),"") | H13: =IF(TEXT(カレンダー!H12,"yyyy年m月")=TEXT($C$10,"yyyy年m月"),INDEX(横カレンダー!$C$4:$IV$13,MATCH($B$13,横カレンダー!$B$4:$B$13,0),MATCH(カレンダー!H12,横カレンダー!$C$3:$IV$3,0)),"") -> #N/A | I13: =IF(TEXT(カレンダー!I12,"yyyy年m月")=TEXT($C$10,"yyyy年m月"),INDEX(横カレンダー!$C$4:$IV$13,MATCH($B$13,横カレンダー!$B$4:$B$13,0),MATCH(カレンダー!I12,横カレンダー!$C$3:$IV$3,0)),"") -> #N/A | K13: =IF(TEXT(カレンダー!K12,"yyyy年m月")=TEXT($K$10,"yyyy年m月"),INDEX(横カレンダー!$C$4:$IV$13,MATCH($B$13,横カレンダー!$B$4:$B$13,0),MATCH(カレンダー!K12,横カレンダー!$C$3:$IV$3,0)),"") | L13: =IF(TEXT(カレンダー!L12,"yyyy年m月")=TEXT($K$10,"yyyy年m月"),INDEX(横カレンダー!$C$4:$IV$13,MATCH($B$13,横カレンダー!$B$4:$B$13,0),MATCH(カレンダー!L12,横カレンダー!$C$3:$IV$3,0)),"") -> #N/A | M13: =IF(TEXT(カレンダー!M12,"yyyy年m月")=TEXT($K$10,"yyyy年m月"),INDEX(横カレンダー!$C$4:$IV$13,MATCH($B$13,横カレンダー!$B$4:$B$13,0),MATCH(カレンダー!M12,横カレンダー!$C$3:$IV$3,0)),"") -> #N/A | N13: =IF(TEXT(カレンダー!N12,"yyyy年m月")=TEXT($K$10,"yyyy年m月"),INDEX(横カレンダー!$C$4:$IV$13,MATCH($B$13,横カレンダー!$B$4:$B$13,0),MATCH(カレンダー!N12,横カレンダー!$C$3:$IV$3,0)),"") -> #N/A | O13: =IF(TEXT(カレンダー!O12,"yyyy年m月")=TEXT($K$10,"yyyy年m月"),INDEX(横カレンダー!$C$4:$IV$13,MATCH($B$13,横カレンダー!$B$4:$B$13,0),MATCH(カレンダー!O12,横カレンダー!$C$3:$IV$3,0)),"") -> #N/A | P13: =IF(TEXT(カレンダー!P12,"yyyy年m月")=TEXT($K$10,"yyyy年m月"),INDEX(横カレンダー!$C$4:$IV$13,MATCH($B$13,横カレンダー!$B$4:$B$13,0),MATCH(カレンダー!P12,横カレンダー!$C$3:$IV$3,0)),"") -> #N/A | Q13: =IF(TEXT(カレンダー!Q12,"yyyy年m月")=TEXT($K$10,"yyyy年m月"),INDEX(横カレンダー!$C$4:$IV$13,MATCH($B$13,横カレンダー!$B$4:$B$13,0),MATCH(カレンダー!Q12,横カレンダー!$C$3:$IV$3,0)),"") -> #N/A | S13: =IF(TEXT(カレンダー!S12,"yyyy年m月")=TEXT($S$10,"yyyy年m月"),INDEX(横カレンダー!$C$4:$IV$13,MATCH($B$13,横カレンダー!$B$4:$B$13,0),MATCH(カレンダー!S12,横カレンダー!$C$3:$IV$3,0)),"") | T13: =IF(TEXT(カレンダー!T12,"yyyy年m月")=TEXT($S$10,"yyyy年m月"),INDEX(横カレンダー!$C$4:$IV$13,MATCH($B$13,横カレンダー!$B$4:$B$13,0),MATCH(カレンダー!T12,横カレンダー!$C$3:$IV$3,0)),"") | U13: =IF(TEXT(カレンダー!U12,"yyyy年m月")=TEXT($S$10,"yyyy年m月"),INDEX(横カレンダー!$C$4:$IV$13,MATCH($B$13,横カレンダー!$B$4:$B$13,0),MATCH(カレンダー!U12,横カレンダー!$C$3:$IV$3,0)),"") | V13: =IF(TEXT(カレンダー!V12,"yyyy年m月")=TEXT($S$10,"yyyy年m月"),INDEX(横カレンダー!$C$4:$IV$13,MATCH($B$13,横カレンダー!$B$4:$B$13,0),MATCH(カレンダー!V12,横カレンダー!$C$3:$IV$3,0)),"") -> #N/A | W13: =IF(TEXT(カレンダー!W12,"yyyy年m月")=TEXT($S$10,"yyyy年m月"),INDEX(横カレンダー!$C$4:$IV$13,MATCH($B$13,横カレンダー!$B$4:$B$13,0),MATCH(カレンダー!W12,横カレンダー!$C$3:$IV$3,0)),"") -> #N/A | X13: =IF(TEXT(カレンダー!X12,"yyyy年m月")=TEXT($S$10,"yyyy年m月"),INDEX(横カレンダー!$C$4:$IV$13,MATCH($B$13,横カレンダー!$B$4:$B$13,0),MATCH(カレンダー!X12,横カレンダー!$C$3:$IV$3,0)),"") -> #N/A | Y13: =IF(TEXT(カレンダー!Y12,"yyyy年m月")=TEXT($S$10,"yyyy年m月"),INDEX(横カレンダー!$C$4:$IV$13,MATCH($B$13,横カレンダー!$B$4:$B$13,0),MATCH(カレンダー!Y12,横カレンダー!$C$3:$IV$3,0)),"") -> #N/A
B14: =MATCH($B$13,B3:B8,0)+1 -> #N/A | C14: =$C$10-WEEKDAY($C$10)+8 -> 45872 | D14: =$C$10-WEEKDAY($C$10)+9 -> 45873 | E14: =$C$10-WEEKDAY($C$10)+10 -> 45874 | F14: =$C$10-WEEKDAY($C$10)+11 -> 45875 | G14: =$C$10-WEEKDAY($C$10)+12 -> 45876 | H14: =$C$10-WEEKDAY($C$10)+13 -> 45877 | I14: =$C$10-WEEKDAY($C$10)+14 -> 45878 | K14: =$K$10-WEEKDAY($K$10)+8 -> 45907 | L14: =$K$10-WEEKDAY($K$10)+9 -> 45908 | M14: =$K$10-WEEKDAY($K$10)+10 -> 45909 | N14: =$K$10-WEEKDAY($K$10)+11 -> 45910 | O14: =$K$10-WEEKDAY($K$10)+12 -> 45911 | P14: =$K$10-WEEKDAY($K$10)+13 -> 45912 | Q14: =$K$10-WEEKDAY($K$10)+14 -> 45913 | S14: =$S$10-WEEKDAY($S$10)+8 -> 45935 | T14: =$S$10-WEEKDAY($S$10)+9 -> 45936 | U14: =$S$10-WEEKDAY($S$10)+10 -> 45937 | V14: =$S$10-WEEKDAY($S$10)+11 -> 45938 | W14: =$S$10-WEEKDAY($S$10)+12 -> 45939 | X14: =$S$10-WEEKDAY($S$10)+13 -> 45940 | Y14: =$S$10-WEEKDAY($S$10)+14 -> 45941
B15: ↓カレンダーリスト | C15: =IF(TEXT(カレンダー!C14,"yyyy年m月")=TEXT($C$10,"yyyy年m月"),INDEX(横カレンダー!$C$4:$IV$13,MATCH($B$13,横カレンダー!$B$4:$B$13,0),MATCH(カレンダー!C14,横カレンダー!$C$3:$IV$3,0)),"") -> #N/A | D15: =IF(TEXT(カレンダー!D14,"yyyy年m月")=TEXT($C$10,"yyyy年m月"),INDEX(横カレンダー!$C$4:$IV$13,MATCH($B$13,横カレンダー!$B$4:$B$13,0),MATCH(カレンダー!D14,横カレンダー!$C$3:$IV$3,0)),"") -> #N/A | E15: =IF(TEXT(カレンダー!E14,"yyyy年m月")=TEXT($C$10,"yyyy年m月"),INDEX(横カレンダー!$C$4:$IV$13,MATCH($B$13,横カレンダー!$B$4:$B$13,0),MATCH(カレンダー!E14,横カレンダー!$C$3:$IV$3,0)),"") -> #N/A | F15: =IF(TEXT(カレンダー!F14,"yyyy年m月")=TEXT($C$10,"yyyy年m月"),INDEX(横カレンダー!$C$4:$IV$13,MATCH($B$13,横カレンダー!$B$4:$B$13,0),MATCH(カレンダー!F14,横カレンダー!$C$3:$IV$3,0)),"") -> #N/A | G15: =IF(TEXT(カレンダー!G14,"yyyy年m月")=TEXT($C$10,"yyyy年m月"),INDEX(横カレンダー!$C$4:$IV$13,MATCH($B$13,横カレンダー!$B$4:$B$13,0),MATCH(カレンダー!G14,横カレンダー!$C$3:$IV$3,0)),"") -> #N/A | H15: =IF(TEXT(カレンダー!H14,"yyyy年m月")=TEXT($C$10,"yyyy年m月"),INDEX(横カレンダー!$C$4:$IV$13,MATCH($B$13,横カレンダー!$B$4:$B$13,0),MATCH(カレンダー!H14,横カレンダー!$C$3:$IV$3,0)),"") -> #N/A | I15: =IF(TEXT(カレンダー!I14,"yyyy年m月")=TEXT($C$10,"yyyy年m月"),INDEX(横カレンダー!$C$4:$IV$13,MATCH($B$13,横カレンダー!$B$4:$B$13,0),MATCH(カレンダー!I14,横カレンダー!$C$3:$IV$3,0)),"") -> #N/A | K15: =IF(TEXT(カレンダー!K14,"yyyy年m月")=TEXT($K$10,"yyyy年m月"),INDEX(横カレンダー!$C$4:$IV$13,MATCH($B$13,横カレンダー!$B$4:$B$13,0),MATCH(カレンダー!K14,横カレンダー!$C$3:$IV$3,0)),"") -> #N/A | L15: =IF(TEXT(カレンダー!L14,"yyyy年m月")=TEXT($K$10,"yyyy年m月"),INDEX(横カレンダー!$C$4:$IV$13,MATCH($B$13,横カレンダー!$B$4:$B$13,0),MATCH(カレンダー!L14,横カレンダー!$C$3:$IV$3,0)),"") -> #N/A | M15: =IF(TEXT(カレンダー!M14,"yyyy年m月")=TEXT($K$10,"yyyy年m月"),INDEX(横カレンダー!$C$4:$IV$13,MATCH($B$13,横カレンダー!$B$4:$B$13,0),MATCH(カレンダー!M14,横カレンダー!$C$3:$IV$3,0)),"") -> #N/A | N15: =IF(TEXT(カレンダー!N14,"yyyy年m月")=TEXT($K$10,"yyyy年m月"),INDEX(横カレンダー!$C$4:$IV$13,MATCH($B$13,横カレンダー!$B$4:$B$13,0),MATCH(カレンダー!N14,横カレンダー!$C$3:$IV$3,0)),"") -> #N/A | O15: =IF(TEXT(カレンダー!O14,"yyyy年m月")=TEXT($K$10,"yyyy年m月"),INDEX(横カレンダー!$C$4:$IV$13,MATCH($B$13,横カレンダー!$B$4:$B$13,0),MATCH(カレンダー!O14,横カレンダー!$C$3:$IV$3,0)),"") -> #N/A | P15: =IF(TEXT(カレンダー!P14,"yyyy年m月")=TEXT($K$10,"yyyy年m月"),INDEX(横カレンダー!$C$4:$IV$13,MATCH($B$13,横カレンダー!$B$4:$B$13,0),MATCH(カレンダー!P14,横カレンダー!$C$3:$IV$3,0)),"") -> #N/A | Q15: =IF(TEXT(カレンダー!Q14,"yyyy年m月")=TEXT($K$10,"yyyy年m月"),INDEX(横カレンダー!$C$4:$IV$13,MATCH($B$13,横カレンダー!$B$4:$B$13,0),MATCH(カレンダー!Q14,横カレンダー!$C$3:$IV$3,0)),"") -> #N/A | S15: =IF(TEXT(カレンダー!S14,"yyyy年m月")=TEXT($S$10,"yyyy年m月"),INDEX(横カレンダー!$C$4:$IV$13,MATCH($B$13,横カレンダー!$B$4:$B$13,0),MATCH(カレンダー!S14,横カレンダー!$C$3:$IV$3,0)),"") -> #N/A | T15: =IF(TEXT(カレンダー!T14,"yyyy年m月")=TEXT($S$10,"yyyy年m月"),INDEX(横カレンダー!$C$4:$IV$13,MATCH($B$13,横カレンダー!$B$4:$B$13,0),MATCH(カレンダー!T14,横カレンダー!$C$3:$IV$3,0)),"") -> #N/A | U15: =IF(TEXT(カレンダー!U14,"yyyy年m月")=TEXT($S$10,"yyyy年m月"),INDEX(横カレンダー!$C$4:$IV$13,MATCH($B$13,横カレンダー!$B$4:$B$13,0),MATCH(カレンダー!U14,横カレンダー!$C$3:$IV$3,0)),"") -> #N/A | V15: =IF(TEXT(カレンダー!V14,"yyyy年m月")=TEXT($S$10,"yyyy年m月"),INDEX(横カレンダー!$C$4:$IV$13,MATCH($B$13,横カレンダー!$B$4:$B$13,0),MATCH(カレンダー!V14,横カレンダー!$C$3:$IV$3,0)),"") -> #N/A | W15: =IF(TEXT(カレンダー!W14,"yyyy年m月")=TEXT($S$10,"yyyy年m月"),INDEX(横カレンダー!$C$4:$IV$13,MATCH($B$13,横カレンダー!$B$4:$B$13,0),MATCH(カレンダー!W14,横カレンダー!$C$3:$IV$3,0)),"") -> #N/A | X15: =IF(TEXT(カレンダー!X14,"yyyy年m月")=TEXT($S$10,"yyyy年m月"),INDEX(横カレンダー!$C$4:$IV$13,MATCH($B$13,横カレンダー!$B$4:$B$13,0),MATCH(カレンダー!X14,横カレンダー!$C$3:$IV$3,0)),"") -> #N/A | Y15: =IF(TEXT(カレンダー!Y14,"yyyy年m月")=TEXT($S$10,"yyyy年m月"),INDEX(横カレンダー!$C$4:$IV$13,MATCH($B$13,横カレンダー!$B$4:$B$13,0),MATCH(カレンダー!Y14,横カレンダー!$C$3:$IV$3,0)),"") -> #N/A
A16: 1 | B16: ラグジュアリープールヴィラ(単泊) | C16: =$C$10-WEEKDAY($C$10)+15 -> 45879 | D16: =$C$10-WEEKDAY($C$10)+16 -> 45880 | E16: =$C$10-WEEKDAY($C$10)+17 -> 45881 | F16: =$C$10-WEEKDAY($C$10)+18 -> 45882 | G16: =$C$10-WEEKDAY($C$10)+19 -> 45883 | H16: =$C$10-WEEKDAY($C$10)+20 -> 45884 | I16: =$C$10-WEEKDAY($C$10)+21 -> 45885 | K16: =$K$10-WEEKDAY($K$10)+15 -> 45914 | L16: =$K$10-WEEKDAY($K$10)+16 -> 45915 | M16: =$K$10-WEEKDAY($K$10)+17 -> 45916 | N16: =$K$10-WEEKDAY($K$10)+18 -> 45917 | O16: =$K$10-WEEKDAY($K$10)+19 -> 45918 | P16: =$K$10-WEEKDAY($K$10)+20 -> 45919 | Q16: =$K$10-WEEKDAY($K$10)+21 -> 45920 | S16: =$S$10-WEEKDAY($S$10)+15 -> 45942 | T16: =$S$10-WEEKDAY($S$10)+16 -> 45943 | U16: =$S$10-WEEKDAY($S$10)+17 -> 45944 | V16: =$S$10-WEEKDAY($S$10)+18 -> 45945 | W16: =$S$10-WEEKDAY($S$10)+19 -> 45946 | X16: =$S$10-WEEKDAY($S$10)+20 -> 45947 | Y16: =$S$10-WEEKDAY($S$10)+21 -> 45948
A17: 12 | B17: ラグジュアリープールヴィラ(連泊) | C17: =IF(TEXT(カレンダー!C16,"yyyy年m月")=TEXT($C$10,"yyyy年m月"),INDEX(横カレンダー!$C$4:$IV$13,MATCH($B$13,横カレンダー!$B$4:$B$13,0),MATCH(カレンダー!C16,横カレンダー!$C$3:$IV$3,0)),"") -> #N/A | D17: =IF(TEXT(カレンダー!D16,"yyyy年m月")=TEXT($C$10,"yyyy年m月"),INDEX(横カレンダー!$C$4:$IV$13,MATCH($B$13,横カレンダー!$B$4:$B$13,0),MATCH(カレンダー!D16,横カレンダー!$C$3:$IV$3,0)),"") -> #N/A | E17: =IF(TEXT(カレンダー!E16,"yyyy年m月")=TEXT($C$10,"yyyy年m月"),INDEX(横カレンダー!$C$4:$IV$13,MATCH($B$13,横カレンダー!$B$4:$B$13,0),MATCH(カレンダー!E16,横カレンダー!$C$3:$IV$3,0)),"") -> #N/A | F17: =IF(TEXT(カレンダー!F16,"yyyy年m月")=TEXT($C$10,"yyyy年m月"),INDEX(横カレンダー!$C$4:$IV$13,MATCH($B$13,横カレンダー!$B$4:$B$13,0),MATCH(カレンダー!F16,横カレンダー!$C$3:$IV$3,0)),"") -> #N/A | G17: =IF(TEXT(カレンダー!G16,"yyyy年m月")=TEXT($C$10,"yyyy年m月"),INDEX(横カレンダー!$C$4:$IV$13,MATCH($B$13,横カレンダー!$B$4:$B$13,0),MATCH(カレンダー!G16,横カレンダー!$C$3:$IV$3,0)),"") -> #N/A | H17: =IF(TEXT(カレンダー!H16,"yyyy年m月")=TEXT($C$10,"yyyy年m月"),INDEX(横カレンダー!$C$4:$IV$13,MATCH($B$13,横カレンダー!$B$4:$B$13,0),MATCH(カレンダー!H16,横カレンダー!$C$3:$IV$3,0)),"") -> #N/A | I17: =IF(TEXT(カレンダー!I16,"yyyy年m月")=TEXT($C$10,"yyyy年m月"),INDEX(横カレンダー!$C$4:$IV$13,MATCH($B$13,横カレンダー!$B$4:$B$13,0),MATCH(カレンダー!I16,横カレンダー!$C$3:$IV$3,0)),"") -> #N/A | K17: =IF(TEXT(カレンダー!K16,"yyyy年m月")=TEXT($K$10,"yyyy年m月"),INDEX(横カレンダー!$C$4:$IV$13,MATCH($B$13,横カレンダー!$B$4:$B$13,0),MATCH(カレンダー!K16,横カレンダー!$C$3:$IV$3,0)),"") -> #N/A | L17: =IF(TEXT(カレンダー!L16,"yyyy年m月")=TEXT($K$10,"yyyy年m月"),INDEX(横カレンダー!$C$4:$IV$13,MATCH($B$13,横カレンダー!$B$4:$B$13,0),MATCH(カレンダー!L16,横カレンダー!$C$3:$IV$3,0)),"") -> #N/A | M17: =IF(TEXT(カレンダー!M16,"yyyy年m月")=TEXT($K$10,"yyyy年m月"),INDEX(横カレンダー!$C$4:$IV$13,MATCH($B$13,横カレンダー!$B$4:$B$13,0),MATCH(カレンダー!M16,横カレンダー!$C$3:$IV$3,0)),"") -> #N/A | N17: =IF(TEXT(カレンダー!N16,"yyyy年m月")=TEXT($K$10,"yyyy年m月"),INDEX(横カレンダー!$C$4:$IV$13,MATCH($B$13,横カレンダー!$B$4:$B$13,0),MATCH(カレンダー!N16,横カレンダー!$C$3:$IV$3,0)),"") -> #N/A | O17: =IF(TEXT(カレンダー!O16,"yyyy年m月")=TEXT($K$10,"yyyy年m月"),INDEX(横カレンダー!$C$4:$IV$13,MATCH($B$13,横カレンダー!$B$4:$B$13,0),MATCH(カレンダー!O16,横カレンダー!$C$3:$IV$3,0)),"") -> #N/A | P17: =IF(TEXT(カレンダー!P16,"yyyy年m月")=TEXT($K$10,"yyyy年m月"),INDEX(横カレンダー!$C$4:$IV$13,MATCH($B$13,横カレンダー!$B$4:$B$13,0),MATCH(カレンダー!P16,横カレンダー!$C$3:$IV$3,0)),"") -> #N/A | Q17: =IF(TEXT(カレンダー!Q16,"yyyy年m月")=TEXT($K$10,"yyyy年m月"),INDEX(横カレンダー!$C$4:$IV$13,MATCH($B$13,横カレンダー!$B$4:$B$13,0),MATCH(カレンダー!Q16,横カレンダー!$C$3:$IV$3,0)),"") -> #N/A | S17: =IF(TEXT(カレンダー!S16,"yyyy年m月")=TEXT($S$10,"yyyy年m月"),INDEX(横カレンダー!$C$4:$IV$13,MATCH($B$13,横カレンダー!$B$4:$B$13,0),MATCH(カレンダー!S16,横カレンダー!$C$3:$IV$3,0)),"") -> #N/A | T17: =IF(TEXT(カレンダー!T16,"yyyy年m月")=TEXT($S$10,"yyyy年m月"),INDEX(横カレンダー!$C$4:$IV$13,MATCH($B$13,横カレンダー!$B$4:$B$13,0),MATCH(カレンダー!T16,横カレンダー!$C$3:$IV$3,0)),"") -> #N/A | U17: =IF(TEXT(カレンダー!U16,"yyyy年m月")=TEXT($S$10,"yyyy年m月"),INDEX(横カレンダー!$C$4:$IV$13,MATCH($B$13,横カレンダー!$B$4:$B$13,0),MATCH(カレンダー!U16,横カレンダー!$C$3:$IV$3,0)),"") -> #N/A | V17: =IF(TEXT(カレンダー!V16,"yyyy年m月")=TEXT($S$10,"yyyy年m月"),INDEX(横カレンダー!$C$4:$IV$13,MATCH($B$13,横カレンダー!$B$4:$B$13,0),MATCH(カレンダー!V16,横カレンダー!$C$3:$IV$3,0)),"") -> #N/A | W17: =IF(TEXT(カレンダー!W16,"yyyy年m月")=TEXT($S$10,"yyyy年m月"),INDEX(横カレンダー!$C$4:$IV$13,MATCH($B$13,横カレンダー!$B$4:$B$13,0),MATCH(カレンダー!W16,横カレンダー!$C$3:$IV$3,0)),"") -> #N/A | X17: =IF(TEXT(カレンダー!X16,"yyyy年m月")=TEXT($S$10,"yyyy年m月"),INDEX(横カレンダー!$C$4:$IV$13,MATCH($B$13,横カレンダー!$B$4:$B$13,0),MATCH(カレンダー!X16,横カレンダー!$C$3:$IV$3,0)),"") -> #N/A | Y17: =IF(TEXT(カレンダー!Y16,"yyyy年m月")=TEXT($S$10,"yyyy年m月"),INDEX(横カレンダー!$C$4:$IV$13,MATCH($B$13,横カレンダー!$B$4:$B$13,0),MATCH(カレンダー!Y16,横カレンダー!$C$3:$IV$3,0)),"") -> #N/A
A18: 6 | B18: with SAUNA(単泊) | C18: =$C$10-WEEKDAY($C$10)+22 -> 45886 | D18: =$C$10-WEEKDAY($C$10)+23 -> 45887 | E18: =$C$10-WEEKDAY($C$10)+24 -> 45888 | F18: =$C$10-WEEKDAY($C$10)+25 -> 45889 | G18: =$C$10-WEEKDAY($C$10)+26 -> 45890 | H18: =$C$10-WEEKDAY($C$10)+27 -> 45891 | I18: =$C$10-WEEKDAY($C$10)+28 -> 45892 | K18: =$K$10-WEEKDAY($K$10)+22 -> 45921 | L18: =$K$10-WEEKDAY($K$10)+23 -> 45922 | M18: =$K$10-WEEKDAY($K$10)+24 -> 45923 | N18: =$K$10-WEEKDAY($K$10)+25 -> 45924 | O18: =$K$10-WEEKDAY($K$10)+26 -> 45925 | P18: =$K$10-WEEKDAY($K$10)+27 -> 45926 | Q18: =$K$10-WEEKDAY($K$10)+28 -> 45927 | S18: =$S$10-WEEKDAY($S$10)+22 -> 45949 | T18: =$S$10-WEEKDAY($S$10)+23 -> 45950 | U18: =$S$10-WEEKDAY($S$10)+24 -> 45951 | V18: =$S$10-WEEKDAY($S$10)+25 -> 45952 | W18: =$S$10-WEEKDAY($S$10)+26 -> 45953 | X18: =$S$10-WEEKDAY($S$10)+27 -> 45954 | Y18: =$S$10-WEEKDAY($S$10)+28 -> 45955
A19: 13 | B19: with SAUNA(連泊) | C19: =IF(TEXT(カレンダー!C18,"yyyy年m月")=TEXT($C$10,"yyyy年m月"),INDEX(横カレンダー!$C$4:$IV$13,MATCH($B$13,横カレンダー!$B$4:$B$13,0),MATCH(カレンダー!C18,横カレンダー!$C$3:$IV$3,0)),"") -> #N/A | D19: =IF(TEXT(カレンダー!D18,"yyyy年m月")=TEXT($C$10,"yyyy年m月"),INDEX(横カレンダー!$C$4:$IV$13,MATCH($B$13,横カレンダー!$B$4:$B$13,0),MATCH(カレンダー!D18,横カレンダー!$C$3:$IV$3,0)),"") -> #N/A | E19: =IF(TEXT(カレンダー!E18,"yyyy年m月")=TEXT($C$10,"yyyy年m月"),INDEX(横カレンダー!$C$4:$IV$13,MATCH($B$13,横カレンダー!$B$4:$B$13,0),MATCH(カレンダー!E18,横カレンダー!$C$3:$IV$3,0)),"") -> #N/A | F19: =IF(TEXT(カレンダー!F18,"yyyy年m月")=TEXT($C$10,"yyyy年m月"),INDEX(横カレンダー!$C$4:$IV$13,MATCH($B$13,横カレンダー!$B$4:$B$13,0),MATCH(カレンダー!F18,横カレンダー!$C$3:$IV$3,0)),"") -> #N/A | G19: =IF(TEXT(カレンダー!G18,"yyyy年m月")=TEXT($C$10,"yyyy年m月"),INDEX(横カレンダー!$C$4:$IV$13,MATCH($B$13,横カレンダー!$B$4:$B$13,0),MATCH(カレンダー!G18,横カレンダー!$C$3:$IV$3,0)),"") -> #N/A | H19: =IF(TEXT(カレンダー!H18,"yyyy年m月")=TEXT($C$10,"yyyy年m月"),INDEX(横カレンダー!$C$4:$IV$13,MATCH($B$13,横カレンダー!$B$4:$B$13,0),MATCH(カレンダー!H18,横カレンダー!$C$3:$IV$3,0)),"") -> #N/A | I19: =IF(TEXT(カレンダー!I18,"yyyy年m月")=TEXT($C$10,"yyyy年m月"),INDEX(横カレンダー!$C$4:$IV$13,MATCH($B$13,横カレンダー!$B$4:$B$13,0),MATCH(カレンダー!I18,横カレンダー!$C$3:$IV$3,0)),"") -> #N/A | K19: =IF(TEXT(カレンダー!K18,"yyyy年m月")=TEXT($K$10,"yyyy年m月"),INDEX(横カレンダー!$C$4:$IV$13,MATCH($B$13,横カレンダー!$B$4:$B$13,0),MATCH(カレンダー!K18,横カレンダー!$C$3:$IV$3,0)),"") -> #N/A | L19: =IF(TEXT(カレンダー!L18,"yyyy年m月")=TEXT($K$10,"yyyy年m月"),INDEX(横カレンダー!$C$4:$IV$13,MATCH($B$13,横カレンダー!$B$4:$B$13,0),MATCH(カレンダー!L18,横カレンダー!$C$3:$IV$3,0)),"") -> #N/A | M19: =IF(TEXT(カレンダー!M18,"yyyy年m月")=TEXT($K$10,"yyyy年m月"),INDEX(横カレンダー!$C$4:$IV$13,MATCH($B$13,横カレンダー!$B$4:$B$13,0),MATCH(カレンダー!M18,横カレンダー!$C$3:$IV$3,0)),"") -> #N/A | N19: =IF(TEXT(カレンダー!N18,"yyyy年m月")=TEXT($K$10,"yyyy年m月"),INDEX(横カレンダー!$C$4:$IV$13,MATCH($B$13,横カレンダー!$B$4:$B$13,0),MATCH(カレンダー!N18,横カレンダー!$C$3:$IV$3,0)),"") -> #N/A | O19: =IF(TEXT(カレンダー!O18,"yyyy年m月")=TEXT($K$10,"yyyy年m月"),INDEX(横カレンダー!$C$4:$IV$13,MATCH($B$13,横カレンダー!$B$4:$B$13,0),MATCH(カレンダー!O18,横カレンダー!$C$3:$IV$3,0)),"") -> #N/A | P19: =IF(TEXT(カレンダー!P18,"yyyy年m月")=TEXT($K$10,"yyyy年m月"),INDEX(横カレンダー!$C$4:$IV$13,MATCH($B$13,横カレンダー!$B$4:$B$13,0),MATCH(カレンダー!P18,横カレンダー!$C$3:$IV$3,0)),"") -> #N/A | Q19: =IF(TEXT(カレンダー!Q18,"yyyy年m月")=TEXT($K$10,"yyyy年m月"),INDEX(横カレンダー!$C$4:$IV$13,MATCH($B$13,横カレンダー!$B$4:$B$13,0),MATCH(カレンダー!Q18,横カレンダー!$C$3:$IV$3,0)),"") -> #N/A | S19: =IF(TEXT(カレンダー!S18,"yyyy年m月")=TEXT($S$10,"yyyy年m月"),INDEX(横カレンダー!$C$4:$IV$13,MATCH($B$13,横カレンダー!$B$4:$B$13,0),MATCH(カレンダー!S18,横カレンダー!$C$3:$IV$3,0)),"") -> #N/A | T19: =IF(TEXT(カレンダー!T18,"yyyy年m月")=TEXT($S$10,"yyyy年m月"),INDEX(横カレンダー!$C$4:$IV$13,MATCH($B$13,横カレンダー!$B$4:$B$13,0),MATCH(カレンダー!T18,横カレンダー!$C$3:$IV$3,0)),"") -> #N/A | U19: =IF(TEXT(カレンダー!U18,"yyyy年m月")=TEXT($S$10,"yyyy年m月"),INDEX(横カレンダー!$C$4:$IV$13,MATCH($B$13,横カレンダー!$B$4:$B$13,0),MATCH(カレンダー!U18,横カレンダー!$C$3:$IV$3,0)),"") -> #N/A | V19: =IF(TEXT(カレンダー!V18,"yyyy年m月")=TEXT($S$10,"yyyy年m月"),INDEX(横カレンダー!$C$4:$IV$13,MATCH($B$13,横カレンダー!$B$4:$B$13,0),MATCH(カレンダー!V18,横カレンダー!$C$3:$IV$3,0)),"") -> #N/A | W19: =IF(TEXT(カレンダー!W18,"yyyy年m月")=TEXT($S$10,"yyyy年m月"),INDEX(横カレンダー!$C$4:$IV$13,MATCH($B$13,横カレンダー!$B$4:$B$13,0),MATCH(カレンダー!W18,横カレンダー!$C$3:$IV$3,0)),"") -> #N/A | X19: =IF(TEXT(カレンダー!X18,"yyyy年m月")=TEXT($S$10,"yyyy年m月"),INDEX(横カレンダー!$C$4:$IV$13,MATCH($B$13,横カレンダー!$B$4:$B$13,0),MATCH(カレンダー!X18,横カレンダー!$C$3:$IV$3,0)),"") -> #N/A | Y19: =IF(TEXT(カレンダー!Y18,"yyyy年m月")=TEXT($S$10,"yyyy年m月"),INDEX(横カレンダー!$C$4:$IV$13,MATCH($B$13,横カレンダー!$B$4:$B$13,0),MATCH(カレンダー!Y18,横カレンダー!$C$3:$IV$3,0)),"") -> #N/A
